Workbook
Name Tol_Amount: SETTINGS!$C$5
Name Tol_Days: SETTINGS!$C$6
Name Tol_NearPct: SETTINGS!$C$7
Name Rpt_Period: SETTINGS!$C$8
Name Co_Name: SETTINGS!$C$13
Name Co_BankAcct: SETTINGS!$C$14
Name Co_IBAN: SETTINGS!$C$15
Name Co_Currency: SETTINGS!$C$16
Name Co_BankName: SETTINGS!$C$17

Sheet README
B2: نظام مطابقة الحسابات البنكية
B3: BANK RECONCILIATION SYSTEM
B5: الغرض من هذا الملف
B6: يقوم هذا الملف بمطابقة كشف الحساب البنكي مع قيود دفتر الأستاذ العام تلقائياً.
B7: يتم احتساب حالة كل قيد: مطابق، قريب من المطابقة، أو غير مطابق.
B9: خطوات الاستخدام
B10: 1. افتح ورقة SETTINGS واضبط إعدادات التسامح والشركة.
B11: 2. الصق بيانات كشف البنك في ورقة BANK_RAW (بدون عناوين الأعمدة).
B12: 3. الصق بيانات الأستاذ العام في ورقة GL_RAW (بدون عناوين الأعمدة).
B13: 4. ستقوم أوراق BANK_CLEAN و GL_CLEAN بتنظيف البيانات تلقائياً.
B14: 5. ورقة MATCH_ENGINE تنفذ المطابقة تلقائياً.
B15: 6. راجع النتائج في RECON_RESULTS.
... B34: الملف مصمم لـ Microsoft Excel 365.

Sheet SETTINGS
B2: إعدادات النظام — SYSTEM SETTINGS
B4: الإعداد | C4: القيمة | D4: الوصف
B5: فرق المبلغ المسموح (SAR) | C5: 1 | D5: Amount Tolerance — الحد الأقصى للفرق بالريال
B6: فرق الأيام المسموح | C6: 1 | D6: Date Tolerance — الحد الأقصى للفرق بالأيام
B7: حد المطابقة القريبة (%) | C7: 50 | D7: Near Match Threshold — أقل نسبة تطابق للمطابقة القريبة
B8: فترة التقرير | C8: 2025-Q1 | D8: Reporting Period
B10: معلومات الشركة — COMPANY INFO
B12: الإعداد | C12: القيمة | D12: الوصف
B13: اسم الشركة | C13: شركة المثال التجارية | D13: Company Name
B14: اسم الحساب البنكي | C14: الحساب الجاري الرئيسي | D14: Bank Account Name
B15: رقم الحساب البنكي | C15: SA0380000000608010167519 | D15: Bank Account Number (IBAN)
B16: العملة | C16: SAR | D16: Currency
B17: اسم البنك | C17: البنك الأهلي السعودي | D17: Bank Name

Sheet BANK_RAW
A1: التاريخ Date | B1: الوصف Description | C1: النوع Type | D1: الدائن Credit | E1: المدين Debit | F1: الرصيد Balance

Sheet GL_RAW
A1: التاريخ Date | B1: رقم القيد JE Number | C1: مفتاح الترحيل Posting Key | D1: نوع القيد JE Type | E1: المبلغ Amount | F1: رقم الحساب GL Account | G1: اسم الحساب GL Name

Sheet BANK_CLEAN
A1: معرف Row ID | B1: التاريخ Date | C1: الوصف Description | D1: النوع Type | E1: الدائن Credit | F1: المدين Debit | G1: الرصيد Balance | H1: الجانب Side | I1: المبلغ Amount | J1: المبلغ المطلق Abs Amount | K1: نوع المطابقة Match Key | L1: مستخدم Used | M1: ملاحظات Notes
A2: =IF(BANK_RAW!A2="","",ROW()-1) | B2: =IF(BANK_RAW!A2="","",IF(ISNUMBER(BANK_RAW!A2),BANK_RAW!A2,DATEVALUE(TEXT(BANK_RAW!A2,"YYYY-MM-DD")))) | C2: =IF(BANK_RAW!A2="","",TRIM(BANK_RAW!B2)) | D2: =IF(BANK_RAW!A2="","",TRIM(BANK_RAW!C2)) | E2: =IF(BANK_RAW!A2="","",IFERROR(ABS(BANK_RAW!D2),0)) | F2: =IF(BANK_RAW!A2="","",IFERROR(ABS(BANK_RAW!E2),0)) | G2: =IF(BANK_RAW!A2="","",IFERROR(BANK_RAW!F2,0)) | H2: =IF(BANK_RAW!A2="","",IF(E2>0,"CR",IF(F2>0,"DR","CR"))) | I2: =IF(BANK_RAW!A2="","",E2-F2) | J2: =IF(BANK_RAW!A2="","",ABS(I2)) | K2: =IF(BANK_RAW!A2="","",IF(H2="CR","IN","OUT"))
A3: =IF(BANK_RAW!A3="","",ROW()-1) | B3: =IF(BANK_RAW!A3="","",IF(ISNUMBER(BANK_RAW!A3),BANK_RAW!A3,DATEVALUE(TEXT(BANK_RAW!A3,"YYYY-MM-DD")))) | C3: =IF(BANK_RAW!A3="","",TRIM(BANK_RAW!B3)) | D3: =IF(BANK_RAW!A3="","",TRIM(BANK_RAW!C3)) | E3: =IF(BANK_RAW!A3="","",IFERROR(ABS(BANK_RAW!D3),0)) | F3: =IF(BANK_RAW!A3="","",IFERROR(ABS(BANK_RAW!E3),0)) | G3: =IF(BANK_RAW!A3="","",IFERROR(BANK_RAW!F3,0)) | H3: =IF(BANK_RAW!A3="","",IF(E3>0,"CR",IF(F3>0,"DR","CR"))) | I3: =IF(BANK_RAW!A3="","",E3-F3) | J3: =IF(BANK_RAW!A3="","",ABS(I3)) | K3: =IF(BANK_RAW!A3="","",IF(H3="CR","IN","OUT"))
A4: =IF(BANK_RAW!A4="","",ROW()-1) | B4: =IF(BANK_RAW!A4="","",IF(ISNUMBER(BANK_RAW!A4),BANK_RAW!A4,DATEVALUE(TEXT(BANK_RAW!A4,"YYYY-MM-DD")))) | C4: =IF(BANK_RAW!A4="","",TRIM(BANK_RAW!B4)) | D4: =IF(BANK_RAW!A4="","",TRIM(BANK_RAW!C4)) | E4: =IF(BANK_RAW!A4="","",IFERROR(ABS(BANK_RAW!D4),0)) | F4: =IF(BANK_RAW!A4="","",IFERROR(ABS(BANK_RAW!E4),0)) | G4: =IF(BANK_RAW!A4="","",IFERROR(BANK_RAW!F4,0)) | H4: =IF(BANK_RAW!A4="","",IF(E4>0,"CR",IF(F4>0,"DR","CR"))) | I4: =IF(BANK_RAW!A4="","",E4-F4) | J4: =IF(BANK_RAW!A4="","",ABS(I4)) | K4: =IF(BANK_RAW!A4="","",IF(H4="CR","IN","OUT"))
A5: =IF(BANK_RAW!A5="","",ROW()-1) | B5: =IF(BANK_RAW!A5="","",IF(ISNUMBER(BANK_RAW!A5),BANK_RAW!A5,DATEVALUE(TEXT(BANK_RAW!A5,"YYYY-MM-DD")))) | C5: =IF(BANK_RAW!A5="","",TRIM(BANK_RAW!B5)) | D5: =IF(BANK_RAW!A5="","",TRIM(BANK_RAW!C5)) | E5: =IF(BANK_RAW!A5="","",IFERROR(ABS(BANK_RAW!D5),0)) | F5: =IF(BANK_RAW!A5="","",IFERROR(ABS(BANK_RAW!E5),0)) | G5: =IF(BANK_RAW!A5="","",IFERROR(BANK_RAW!F5,0)) | H5: =IF(BANK_RAW!A5="","",IF(E5>0,"CR",IF(F5>0,"DR","CR"))) | I5: =IF(BANK_RAW!A5="","",E5-F5) | J5: =IF(BANK_RAW!A5="","",ABS(I5)) | K5: =IF(BANK_RAW!A5="","",IF(H5="CR","IN","OUT"))
A6: =IF(BANK_RAW!A6="","",ROW()-1) | B6: =IF(BANK_RAW!A6="","",IF(ISNUMBER(BANK_RAW!A6),BANK_RAW!A6,DATEVALUE(TEXT(BANK_RAW!A6,"YYYY-MM-DD")))) | C6: =IF(BANK_RAW!A6="","",TRIM(BANK_RAW!B6)) | D6: =IF(BANK_RAW!A6="","",TRIM(BANK_RAW!C6)) | E6: =IF(BANK_RAW!A6="","",IFERROR(ABS(BANK_RAW!D6),0)) | F6: =IF(BANK_RAW!A6="","",IFERROR(ABS(BANK_RAW!E6),0)) | G6: =IF(BANK_RAW!A6="","",IFERROR(BANK_RAW!F6,0)) | H6: =IF(BANK_RAW!A6="","",IF(E6>0,"CR",IF(F6>0,"DR","CR"))) | I6: =IF(BANK_RAW!A6="","",E6-F6) | J6: =IF(BANK_RAW!A6="","",ABS(I6)) | K6: =IF(BANK_RAW!A6="","",IF(H6="CR","IN","OUT"))
A7: =IF(BANK_RAW!A7="","",ROW()-1) | B7: =IF(BANK_RAW!A7="","",IF(ISNUMBER(BANK_RAW!A7),BANK_RAW!A7,DATEVALUE(TEXT(BANK_RAW!A7,"YYYY-MM-DD")))) | C7: =IF(BANK_RAW!A7="","",TRIM(BANK_RAW!B7)) | D7: =IF(BANK_RAW!A7="","",TRIM(BANK_RAW!C7)) | E7: =IF(BANK_RAW!A7="","",IFERROR(ABS(BANK_RAW!D7),0)) | F7: =IF(BANK_RAW!A7="","",IFERROR(ABS(BANK_RAW!E7),0)) | G7: =IF(BANK_RAW!A7="","",IFERROR(BANK_RAW!F7,0)) | H7: =IF(BANK_RAW!A7="","",IF(E7>0,"CR",IF(F7>0,"DR","CR"))) | I7: =IF(BANK_RAW!A7="","",E7-F7) | J7: =IF(BANK_RAW!A7="","",ABS(I7)) | K7: =IF(BANK_RAW!A7="","",IF(H7="CR","IN","OUT"))
A8: =IF(BANK_RAW!A8="","",ROW()-1) | B8: =IF(BANK_RAW!A8="","",IF(ISNUMBER(BANK_RAW!A8),BANK_RAW!A8,DATEVALUE(TEXT(BANK_RAW!A8,"YYYY-MM-DD")))) | C8: =IF(BANK_RAW!A8="","",TRIM(BANK_RAW!B8)) | D8: =IF(BANK_RAW!A8="","",TRIM(BANK_RAW!C8)) | E8: =IF(BANK_RAW!A8="","",IFERROR(ABS(BANK_RAW!D8),0)) | F8: =IF(BANK_RAW!A8="","",IFERROR(ABS(BANK_RAW!E8),0)) | G8: =IF(BANK_RAW!A8="","",IFERROR(BANK_RAW!F8,0)) | H8: =IF(BANK_RAW!A8="","",IF(E8>0,"CR",IF(F8>0,"DR","CR"))) | I8: =IF(BANK_RAW!A8="","",E8-F8) | J8: =IF(BANK_RAW!A8="","",ABS(I8)) | K8: =IF(BANK_RAW!A8="","",IF(H8="CR","IN","OUT"))
A9: =IF(BANK_RAW!A9="","",ROW()-1) | B9: =IF(BANK_RAW!A9="","",IF(ISNUMBER(BANK_RAW!A9),BANK_RAW!A9,DATEVALUE(TEXT(BANK_RAW!A9,"YYYY-MM-DD")))) | C9: =IF(BANK_RAW!A9="","",TRIM(BANK_RAW!B9)) | D9: =IF(BANK_RAW!A9="","",TRIM(BANK_RAW!C9)) | E9: =IF(BANK_RAW!A9="","",IFERROR(ABS(BANK_RAW!D9),0)) | F9: =IF(BANK_RAW!A9="","",IFERROR(ABS(BANK_RAW!E9),0)) | G9: =IF(BANK_RAW!A9="","",IFERROR(BANK_RAW!F9,0)) | H9: =IF(BANK_RAW!A9="","",IF(E9>0,"CR",IF(F9>0,"DR","CR"))) | I9: =IF(BANK_RAW!A9="","",E9-F9) | J9: =IF(BANK_RAW!A9="","",ABS(I9)) | K9: =IF(BANK_RAW!A9="","",IF(H9="CR","IN","OUT"))
A10: =IF(BANK_RAW!A10="","",ROW()-1) | B10: =IF(BANK_RAW!A10="","",IF(ISNUMBER(BANK_RAW!A10),BANK_RAW!A10,DATEVALUE(TEXT(BANK_RAW!A10,"YYYY-MM-DD")))) | C10: =IF(BANK_RAW!A10="","",TRIM(BANK_RAW!B10)) | D10: =IF(BANK_RAW!A10="","",TRIM(BANK_RAW!C10)) | E10: =IF(BANK_RAW!A10="","",IFERROR(ABS(BANK_RAW!D10),0)) | F10: =IF(BANK_RAW!A10="","",IFERROR(ABS(BANK_RAW!E10),0)) | G10: =IF(BANK_RAW!A10="","",IFERROR(BANK_RAW!F10,0)) | H10: =IF(BANK_RAW!A10="","",IF(E10>0,"CR",IF(F10>0,"DR","CR"))) | I10: =IF(BANK_RAW!A10="","",E10-F10) | J10: =IF(BANK_RAW!A10="","",ABS(I10)) | K10: =IF(BANK_RAW!A10="","",IF(H10="CR","IN","OUT"))
A11: =IF(BANK_RAW!A11="","",ROW()-1) | B11: =IF(BANK_RAW!A11="","",IF(ISNUMBER(BANK_RAW!A11),BANK_RAW!A11,DATEVALUE(TEXT(BANK_RAW!A11,"YYYY-MM-DD")))) | C11: =IF(BANK_RAW!A11="","",TRIM(BANK_RAW!B11)) | D11: =IF(BANK_RAW!A11="","",TRIM(BANK_RAW!C11)) | E11: =IF(BANK_RAW!A11="","",IFERROR(ABS(BANK_RAW!D11),0)) | F11: =IF(BANK_RAW!A11="","",IFERROR(ABS(BANK_RAW!E11),0)) | G11: =IF(BANK_RAW!A11="","",IFERROR(BANK_RAW!F11,0)) | H11: =IF(BANK_RAW!A11="","",IF(E11>0,"CR",IF(F11>0,"DR","CR"))) | I11: =IF(BANK_RAW!A11="","",E11-F11) | J11: =IF(BANK_RAW!A11="","",ABS(I11)) | K11: =IF(BANK_RAW!A11="","",IF(H11="CR","IN","OUT"))
A12: =IF(BANK_RAW!A12="","",ROW()-1) | B12: =IF(BANK_RAW!A12="","",IF(ISNUMBER(BANK_RAW!A12),BANK_RAW!A12,DATEVALUE(TEXT(BANK_RAW!A12,"YYYY-MM-DD")))) | C12: =IF(BANK_RAW!A12="","",TRIM(BANK_RAW!B12)) | D12: =IF(BANK_RAW!A12="","",TRIM(BANK_RAW!C12)) | E12: =IF(BANK_RAW!A12="","",IFERROR(ABS(BANK_RAW!D12),0)) | F12: =IF(BANK_RAW!A12="","",IFERROR(ABS(BANK_RAW!E12),0)) | G12: =IF(BANK_RAW!A12="","",IFERROR(BANK_RAW!F12,0)) | H12: =IF(BANK_RAW!A12="","",IF(E12>0,"CR",IF(F12>0,"DR","CR"))) | I12: =IF(BANK_RAW!A12="","",E12-F12) | J12: =IF(BANK_RAW!A12="","",ABS(I12)) | K12: =IF(BANK_RAW!A12="","",IF(H12="CR","IN","OUT"))
A13: =IF(BANK_RAW!A13="","",ROW()-1) | B13: =IF(BANK_RAW!A13="","",IF(ISNUMBER(BANK_RAW!A13),BANK_RAW!A13,DATEVALUE(TEXT(BANK_RAW!A13,"YYYY-MM-DD")))) | C13: =IF(BANK_RAW!A13="","",TRIM(BANK_RAW!B13)) | D13: =IF(BANK_RAW!A13="","",TRIM(BANK_RAW!C13)) | E13: =IF(BANK_RAW!A13="","",IFERROR(ABS(BANK_RAW!D13),0)) | F13: =IF(BANK_RAW!A13="","",IFERROR(ABS(BANK_RAW!E13),0)) | G13: =IF(BANK_RAW!A13="","",IFERROR(BANK_RAW!F13,0)) | H13: =IF(BANK_RAW!A13="","",IF(E13>0,"CR",IF(F13>0,"DR","CR"))) | I13: =IF(BANK_RAW!A13="","",E13-F13) | J13: =IF(BANK_RAW!A13="","",ABS(I13)) | K13: =IF(BANK_RAW!A13="","",IF(H13="CR","IN","OUT"))
... A1001: =IF(BANK_RAW!A1001="","",ROW()-1) | B1001: =IF(BANK_RAW!A1001="","",IF(ISNUMBER(BANK_RAW!A1001),BANK_RAW!A1001,DATEVALUE(TEXT(BANK_RAW!A1001,"YYYY-MM-DD")))) | C1001: =IF(BANK_RAW!A1001="","",TRIM(BANK_RAW!B1001)) | D1001: =IF(BANK_RAW!A1001="","",TRIM(BANK_RAW!C1001)) | E1001: =IF(BANK_RAW!A1001="","",IFERROR(ABS(BANK_RAW!D1001),0)) | F1001: =IF(BANK_RAW!A1001="","",IFERROR(ABS(BANK_RAW!E1001),0)) | G1001: =IF(BANK_RAW!A1001="","",IFERROR(BANK_RAW!F1001,0)) | H1001: =IF(BANK_RAW!A1001="","",IF(E1001>0,"CR",IF(F1001>0,"DR","CR"))) | I1001: =IF(BANK_RAW!A1001="","",E1001-F1001) | J1001: =IF(BANK_RAW!A1001="","",ABS(I1001)) | K1001: =IF(BANK_RAW!A1001="","",IF(H1001="CR","IN","OUT"))

Sheet GL_CLEAN
A1: معرف Row ID | B1: التاريخ Date | C1: رقم القيد JE Number | D1: مفتاح الترحيل Posting Key | E1: نوع القيد JE Type | F1: رقم الحساب GL Account | G1: اسم الحساب GL Name | H1: المبلغ Amount | I1: المبلغ المطلق Abs Amount | J1: الاتجاه Direction | K1: ملاحظات Notes
A2: =IF(GL_RAW!A2="","",ROW()-1) | B2: =IF(GL_RAW!A2="","",IF(ISNUMBER(GL_RAW!A2),GL_RAW!A2,DATEVALUE(TEXT(GL_RAW!A2,"YYYY-MM-DD")))) | C2: =IF(GL_RAW!A2="","",TRIM(GL_RAW!B2)) | D2: =IF(GL_RAW!A2="","",TRIM(GL_RAW!C2)) | E2: =IF(GL_RAW!A2="","",TRIM(GL_RAW!D2)) | F2: =IF(GL_RAW!A2="","",TRIM(GL_RAW!F2)) | G2: =IF(GL_RAW!A2="","",TRIM(GL_RAW!G2)) | H2: =IF(GL_RAW!A2="","",IFERROR(GL_RAW!E2,0)) | I2: =IF(GL_RAW!A2="","",ABS(H2)) | J2: =IF(GL_RAW!A2="","",IF(OR(ISNUMBER(SEARCH("Out",F2)),ISNUMBER(SEARCH("11025002",F2)),H2<0),"OUT","IN"))
A3: =IF(GL_RAW!A3="","",ROW()-1) | B3: =IF(GL_RAW!A3="","",IF(ISNUMBER(GL_RAW!A3),GL_RAW!A3,DATEVALUE(TEXT(GL_RAW!A3,"YYYY-MM-DD")))) | C3: =IF(GL_RAW!A3="","",TRIM(GL_RAW!B3)) | D3: =IF(GL_RAW!A3="","",TRIM(GL_RAW!C3)) | E3: =IF(GL_RAW!A3="","",TRIM(GL_RAW!D3)) | F3: =IF(GL_RAW!A3="","",TRIM(GL_RAW!F3)) | G3: =IF(GL_RAW!A3="","",TRIM(GL_RAW!G3)) | H3: =IF(GL_RAW!A3="","",IFERROR(GL_RAW!E3,0)) | I3: =IF(GL_RAW!A3="","",ABS(H3)) | J3: =IF(GL_RAW!A3="","",IF(OR(ISNUMBER(SEARCH("Out",F3)),ISNUMBER(SEARCH("11025002",F3)),H3<0),"OUT","IN"))
A4: =IF(GL_RAW!A4="","",ROW()-1) | B4: =IF(GL_RAW!A4="","",IF(ISNUMBER(GL_RAW!A4),GL_RAW!A4,DATEVALUE(TEXT(GL_RAW!A4,"YYYY-MM-DD")))) | C4: =IF(GL_RAW!A4="","",TRIM(GL_RAW!B4)) | D4: =IF(GL_RAW!A4="","",TRIM(GL_RAW!C4)) | E4: =IF(GL_RAW!A4="","",TRIM(GL_RAW!D4)) | F4: =IF(GL_RAW!A4="","",TRIM(GL_RAW!F4)) | G4: =IF(GL_RAW!A4="","",TRIM(GL_RAW!G4)) | H4: =IF(GL_RAW!A4="","",IFERROR(GL_RAW!E4,0)) | I4: =IF(GL_RAW!A4="","",ABS(H4)) | J4: =IF(GL_RAW!A4="","",IF(OR(ISNUMBER(SEARCH("Out",F4)),ISNUMBER(SEARCH("11025002",F4)),H4<0),"OUT","IN"))
A5: =IF(GL_RAW!A5="","",ROW()-1) | B5: =IF(GL_RAW!A5="","",IF(ISNUMBER(GL_RAW!A5),GL_RAW!A5,DATEVALUE(TEXT(GL_RAW!A5,"YYYY-MM-DD")))) | C5: =IF(GL_RAW!A5="","",TRIM(GL_RAW!B5)) | D5: =IF(GL_RAW!A5="","",TRIM(GL_RAW!C5)) | E5: =IF(GL_RAW!A5="","",TRIM(GL_RAW!D5)) | F5: =IF(GL_RAW!A5="","",TRIM(GL_RAW!F5)) | G5: =IF(GL_RAW!A5="","",TRIM(GL_RAW!G5)) | H5: =IF(GL_RAW!A5="","",IFERROR(GL_RAW!E5,0)) | I5: =IF(GL_RAW!A5="","",ABS(H5)) | J5: =IF(GL_RAW!A5="","",IF(OR(ISNUMBER(SEARCH("Out",F5)),ISNUMBER(SEARCH("11025002",F5)),H5<0),"OUT","IN"))
A6: =IF(GL_RAW!A6="","",ROW()-1) | B6: =IF(GL_RAW!A6="","",IF(ISNUMBER(GL_RAW!A6),GL_RAW!A6,DATEVALUE(TEXT(GL_RAW!A6,"YYYY-MM-DD")))) | C6: =IF(GL_RAW!A6="","",TRIM(GL_RAW!B6)) | D6: =IF(GL_RAW!A6="","",TRIM(GL_RAW!C6)) | E6: =IF(GL_RAW!A6="","",TRIM(GL_RAW!D6)) | F6: =IF(GL_RAW!A6="","",TRIM(GL_RAW!F6)) | G6: =IF(GL_RAW!A6="","",TRIM(GL_RAW!G6)) | H6: =IF(GL_RAW!A6="","",IFERROR(GL_RAW!E6,0)) | I6: =IF(GL_RAW!A6="","",ABS(H6)) | J6: =IF(GL_RAW!A6="","",IF(OR(ISNUMBER(SEARCH("Out",F6)),ISNUMBER(SEARCH("11025002",F6)),H6<0),"OUT","IN"))
A7: =IF(GL_RAW!A7="","",ROW()-1) | B7: =IF(GL_RAW!A7="","",IF(ISNUMBER(GL_RAW!A7),GL_RAW!A7,DATEVALUE(TEXT(GL_RAW!A7,"YYYY-MM-DD")))) | C7: =IF(GL_RAW!A7="","",TRIM(GL_RAW!B7)) | D7: =IF(GL_RAW!A7="","",TRIM(GL_RAW!C7)) | E7: =IF(GL_RAW!A7="","",TRIM(GL_RAW!D7)) | F7: =IF(GL_RAW!A7="","",TRIM(GL_RAW!F7)) | G7: =IF(GL_RAW!A7="","",TRIM(GL_RAW!G7)) | H7: =IF(GL_RAW!A7="","",IFERROR(GL_RAW!E7,0)) | I7: =IF(GL_RAW!A7="","",ABS(H7)) | J7: =IF(GL_RAW!A7="","",IF(OR(ISNUMBER(SEARCH("Out",F7)),ISNUMBER(SEARCH("11025002",F7)),H7<0),"OUT","IN"))
A8: =IF(GL_RAW!A8="","",ROW()-1) | B8: =IF(GL_RAW!A8="","",IF(ISNUMBER(GL_RAW!A8),GL_RAW!A8,DATEVALUE(TEXT(GL_RAW!A8,"YYYY-MM-DD")))) | C8: =IF(GL_RAW!A8="","",TRIM(GL_RAW!B8)) | D8: =IF(GL_RAW!A8="","",TRIM(GL_RAW!C8)) | E8: =IF(GL_RAW!A8="","",TRIM(GL_RAW!D8)) | F8: =IF(GL_RAW!A8="","",TRIM(GL_RAW!F8)) | G8: =IF(GL_RAW!A8="","",TRIM(GL_RAW!G8)) | H8: =IF(GL_RAW!A8="","",IFERROR(GL_RAW!E8,0)) | I8: =IF(GL_RAW!A8="","",ABS(H8)) | J8: =IF(GL_RAW!A8="","",IF(OR(ISNUMBER(SEARCH("Out",F8)),ISNUMBER(SEARCH("11025002",F8)),H8<0),"OUT","IN"))
A9: =IF(GL_RAW!A9="","",ROW()-1) | B9: =IF(GL_RAW!A9="","",IF(ISNUMBER(GL_RAW!A9),GL_RAW!A9,DATEVALUE(TEXT(GL_RAW!A9,"YYYY-MM-DD")))) | C9: =IF(GL_RAW!A9="","",TRIM(GL_RAW!B9)) | D9: =IF(GL_RAW!A9="","",TRIM(GL_RAW!C9)) | E9: =IF(GL_RAW!A9="","",TRIM(GL_RAW!D9)) | F9: =IF(GL_RAW!A9="","",TRIM(GL_RAW!F9)) | G9: =IF(GL_RAW!A9="","",TRIM(GL_RAW!G9)) | H9: =IF(GL_RAW!A9="","",IFERROR(GL_RAW!E9,0)) | I9: =IF(GL_RAW!A9="","",ABS(H9)) | J9: =IF(GL_RAW!A9="","",IF(OR(ISNUMBER(SEARCH("Out",F9)),ISNUMBER(SEARCH("11025002",F9)),H9<0),"OUT","IN"))
A10: =IF(GL_RAW!A10="","",ROW()-1) | B10: =IF(GL_RAW!A10="","",IF(ISNUMBER(GL_RAW!A10),GL_RAW!A10,DATEVALUE(TEXT(GL_RAW!A10,"YYYY-MM-DD")))) | C10: =IF(GL_RAW!A10="","",TRIM(GL_RAW!B10)) | D10: =IF(GL_RAW!A10="","",TRIM(GL_RAW!C10)) | E10: =IF(GL_RAW!A10="","",TRIM(GL_RAW!D10)) | F10: =IF(GL_RAW!A10="","",TRIM(GL_RAW!F10)) | G10: =IF(GL_RAW!A10="","",TRIM(GL_RAW!G10)) | H10: =IF(GL_RAW!A10="","",IFERROR(GL_RAW!E10,0)) | I10: =IF(GL_RAW!A10="","",ABS(H10)) | J10: =IF(GL_RAW!A10="","",IF(OR(ISNUMBER(SEARCH("Out",F10)),ISNUMBER(SEARCH("11025002",F10)),H10<0),"OUT","IN"))
A11: =IF(GL_RAW!A11="","",ROW()-1) | B11: =IF(GL_RAW!A11="","",IF(ISNUMBER(GL_RAW!A11),GL_RAW!A11,DATEVALUE(TEXT(GL_RAW!A11,"YYYY-MM-DD")))) | C11: =IF(GL_RAW!A11="","",TRIM(GL_RAW!B11)) | D11: =IF(GL_RAW!A11="","",TRIM(GL_RAW!C11)) | E11: =IF(GL_RAW!A11="","",TRIM(GL_RAW!D11)) | F11: =IF(GL_RAW!A11="","",TRIM(GL_RAW!F11)) | G11: =IF(GL_RAW!A11="","",TRIM(GL_RAW!G11)) | H11: =IF(GL_RAW!A11="","",IFERROR(GL_RAW!E11,0)) | I11: =IF(GL_RAW!A11="","",ABS(H11)) | J11: =IF(GL_RAW!A11="","",IF(OR(ISNUMBER(SEARCH("Out",F11)),ISNUMBER(SEARCH("11025002",F11)),H11<0),"OUT","IN"))
A12: =IF(GL_RAW!A12="","",ROW()-1) | B12: =IF(GL_RAW!A12="","",IF(ISNUMBER(GL_RAW!A12),GL_RAW!A12,DATEVALUE(TEXT(GL_RAW!A12,"YYYY-MM-DD")))) | C12: =IF(GL_RAW!A12="","",TRIM(GL_RAW!B12)) | D12: =IF(GL_RAW!A12="","",TRIM(GL_RAW!C12)) | E12: =IF(GL_RAW!A12="","",TRIM(GL_RAW!D12)) | F12: =IF(GL_RAW!A12="","",TRIM(GL_RAW!F12)) | G12: =IF(GL_RAW!A12="","",TRIM(GL_RAW!G12)) | H12: =IF(GL_RAW!A12="","",IFERROR(GL_RAW!E12,0)) | I12: =IF(GL_RAW!A12="","",ABS(H12)) | J12: =IF(GL_RAW!A12="","",IF(OR(ISNUMBER(SEARCH("Out",F12)),ISNUMBER(SEARCH("11025002",F12)),H12<0),"OUT","IN"))
A13: =IF(GL_RAW!A13="","",ROW()-1) | B13: =IF(GL_RAW!A13="","",IF(ISNUMBER(GL_RAW!A13),GL_RAW!A13,DATEVALUE(TEXT(GL_RAW!A13,"YYYY-MM-DD")))) | C13: =IF(GL_RAW!A13="","",TRIM(GL_RAW!B13)) | D13: =IF(GL_RAW!A13="","",TRIM(GL_RAW!C13)) | E13: =IF(GL_RAW!A13="","",TRIM(GL_RAW!D13)) | F13: =IF(GL_RAW!A13="","",TRIM(GL_RAW!F13)) | G13: =IF(GL_RAW!A13="","",TRIM(GL_RAW!G13)) | H13: =IF(GL_RAW!A13="","",IFERROR(GL_RAW!E13,0)) | I13: =IF(GL_RAW!A13="","",ABS(H13)) | J13: =IF(GL_RAW!A13="","",IF(OR(ISNUMBER(SEARCH("Out",F13)),ISNUMBER(SEARCH("11025002",F13)),H13<0),"OUT","IN"))
... A1001: =IF(GL_RAW!A1001="","",ROW()-1) | B1001: =IF(GL_RAW!A1001="","",IF(ISNUMBER(GL_RAW!A1001),GL_RAW!A1001,DATEVALUE(TEXT(GL_RAW!A1001,"YYYY-MM-DD")))) | C1001: =IF(GL_RAW!A1001="","",TRIM(GL_RAW!B1001)) | D1001: =IF(GL_RAW!A1001="","",TRIM(GL_RAW!C1001)) | E1001: =IF(GL_RAW!A1001="","",TRIM(GL_RAW!D1001)) | F1001: =IF(GL_RAW!A1001="","",TRIM(GL_RAW!F1001)) | G1001: =IF(GL_RAW!A1001="","",TRIM(GL_RAW!G1001)) | H1001: =IF(GL_RAW!A1001="","",IFERROR(GL_RAW!E1001,0)) | I1001: =IF(GL_RAW!A1001="","",ABS(H1001)) | J1001: =IF(GL_RAW!A1001="","",IF(OR(ISNUMBER(SEARCH("Out",F1001)),ISNUMBER(SEARCH("11025002",F1001)),H1001<0),"OUT","IN"))

Sheet MATCH_ENGINE
A1: GL Row معرف GL | B1: GL Date تاريخ GL | C1: GL JE رقم القيد | D1: GL Amount مبلغ GL | E1: GL Abs Amt المبلغ المطلق | F1: GL Direction الاتجاه | G1: Bank Pool مجموعة البنك | H1: Best Bank Row أفضل صف بنك | I1: Best Bank Date تاريخ البنك | J1: Best Bank Amt مبلغ البنك | K1: Amt Diff فرق المبلغ | L1: Days Diff فرق الأيام | M1: Match Score نسبة التطابق | N1: Status الحالة
A2: =IF(GL_CLEAN!A2="","",GL_CLEAN!A2) | B2: =IF(A2="","",GL_CLEAN!B2) | C2: =IF(A2="","",GL_CLEAN!C2) | D2: =IF(A2="","",GL_CLEAN!H2) | E2: =IF(A2="","",GL_CLEAN!I2) | F2: =IF(A2="","",GL_CLEAN!J2) | G2: =IF(A2="","",IF(F2="OUT","DR","CR")) | H2: =IF(A2="","",IFERROR(INDEX(BANK_CLEAN!$A$2:$A$1001,MATCH(MINIFS(BANK_CLEAN!$J$2:$J$1001,BANK_CLEAN!$H$2:$H$1001,G2,BANK_CLEAN!$L$2:$L$1001,""),BANK_CLEAN!$J$2:$J$1001,0)),"")) | I2: =IF(H2="","",INDEX(BANK_CLEAN!$B$2:$B$1001,H2)) | J2: =IF(H2="","",IF(F2="OUT",INDEX(BANK_CLEAN!$F$2:$F$1001,H2),INDEX(BANK_CLEAN!$E$2:$E$1001,H2))) | K2: =IF(H2="","",ABS(E2-J2)) | L2: =IF(OR(H2="",B2="",I2=""),"",ABS(B2-I2)) | M2: =IF(H2="",0,LET(pct,IF(E2>0,K2/E2,1),days,IFERROR(L2,999),100-pct*200-days*3)) | N2: =IF(A2="","",IF(H2="","Unmatched GL",IF(AND(K2<=Tol_Amount,L2<=Tol_Days),"Matched",IF(M2>Tol_NearPct,"Near Match","Unmatched GL"))))
A3: =IF(GL_CLEAN!A3="","",GL_CLEAN!A3) | B3: =IF(A3="","",GL_CLEAN!B3) | C3: =IF(A3="","",GL_CLEAN!C3) | D3: =IF(A3="","",GL_CLEAN!H3) | E3: =IF(A3="","",GL_CLEAN!I3) | F3: =IF(A3="","",GL_CLEAN!J3) | G3: =IF(A3="","",IF(F3="OUT","DR","CR")) | H3: =IF(A3="","",IFERROR(INDEX(BANK_CLEAN!$A$2:$A$1001,MATCH(MINIFS(BANK_CLEAN!$J$2:$J$1001,BANK_CLEAN!$H$2:$H$1001,G3,BANK_CLEAN!$L$2:$L$1001,""),BANK_CLEAN!$J$2:$J$1001,0)),"")) | I3: =IF(H3="","",INDEX(BANK_CLEAN!$B$2:$B$1001,H3)) | J3: =IF(H3="","",IF(F3="OUT",INDEX(BANK_CLEAN!$F$2:$F$1001,H3),INDEX(BANK_CLEAN!$E$2:$E$1001,H3))) | K3: =IF(H3="","",ABS(E3-J3)) | L3: =IF(OR(H3="",B3="",I3=""),"",ABS(B3-I3)) | M3: =IF(H3="",0,LET(pct,IF(E3>0,K3/E3,1),days,IFERROR(L3,999),100-pct*200-days*3)) | N3: =IF(A3="","",IF(H3="","Unmatched GL",IF(AND(K3<=Tol_Amount,L3<=Tol_Days),"Matched",IF(M3>Tol_NearPct,"Near Match","Unmatched GL"))))
A4: =IF(GL_CLEAN!A4="","",GL_CLEAN!A4) | B4: =IF(A4="","",GL_CLEAN!B4) | C4: =IF(A4="","",GL_CLEAN!C4) | D4: =IF(A4="","",GL_CLEAN!H4) | E4: =IF(A4="","",GL_CLEAN!I4) | F4: =IF(A4="","",GL_CLEAN!J4) | G4: =IF(A4="","",IF(F4="OUT","DR","CR")) | H4: =IF(A4="","",IFERROR(INDEX(BANK_CLEAN!$A$2:$A$1001,MATCH(MINIFS(BANK_CLEAN!$J$2:$J$1001,BANK_CLEAN!$H$2:$H$1001,G4,BANK_CLEAN!$L$2:$L$1001,""),BANK_CLEAN!$J$2:$J$1001,0)),"")) | I4: =IF(H4="","",INDEX(BANK_CLEAN!$B$2:$B$1001,H4)) | J4: =IF(H4="","",IF(F4="OUT",INDEX(BANK_CLEAN!$F$2:$F$1001,H4),INDEX(BANK_CLEAN!$E$2:$E$1001,H4))) | K4: =IF(H4="","",ABS(E4-J4)) | L4: =IF(OR(H4="",B4="",I4=""),"",ABS(B4-I4)) | M4: =IF(H4="",0,LET(pct,IF(E4>0,K4/E4,1),days,IFERROR(L4,999),100-pct*200-days*3)) | N4: =IF(A4="","",IF(H4="","Unmatched GL",IF(AND(K4<=Tol_Amount,L4<=Tol_Days),"Matched",IF(M4>Tol_NearPct,"Near Match","Unmatched GL"))))
A5: =IF(GL_CLEAN!A5="","",GL_CLEAN!A5) | B5: =IF(A5="","",GL_CLEAN!B5) | C5: =IF(A5="","",GL_CLEAN!C5) | D5: =IF(A5="","",GL_CLEAN!H5) | E5: =IF(A5="","",GL_CLEAN!I5) | F5: =IF(A5="","",GL_CLEAN!J5) | G5: =IF(A5="","",IF(F5="OUT","DR","CR")) | H5: =IF(A5="","",IFERROR(INDEX(BANK_CLEAN!$A$2:$A$1001,MATCH(MINIFS(BANK_CLEAN!$J$2:$J$1001,BANK_CLEAN!$H$2:$H$1001,G5,BANK_CLEAN!$L$2:$L$1001,""),BANK_CLEAN!$J$2:$J$1001,0)),"")) | I5: =IF(H5="","",INDEX(BANK_CLEAN!$B$2:$B$1001,H5)) | J5: =IF(H5="","",IF(F5="OUT",INDEX(BANK_CLEAN!$F$2:$F$1001,H5),INDEX(BANK_CLEAN!$E$2:$E$1001,H5))) | K5: =IF(H5="","",ABS(E5-J5)) | L5: =IF(OR(H5="",B5="",I5=""),"",ABS(B5-I5)) | M5: =IF(H5="",0,LET(pct,IF(E5>0,K5/E5,1),days,IFERROR(L5,999),100-pct*200-days*3)) | N5: =IF(A5="","",IF(H5="","Unmatched GL",IF(AND(K5<=Tol_Amount,L5<=Tol_Days),"Matched",IF(M5>Tol_NearPct,"Near Match","Unmatched GL"))))
A6: =IF(GL_CLEAN!A6="","",GL_CLEAN!A6) | B6: =IF(A6="","",GL_CLEAN!B6) | C6: =IF(A6="","",GL_CLEAN!C6) | D6: =IF(A6="","",GL_CLEAN!H6) | E6: =IF(A6="","",GL_CLEAN!I6) | F6: =IF(A6="","",GL_CLEAN!J6) | G6: =IF(A6="","",IF(F6="OUT","DR","CR")) | H6: =IF(A6="","",IFERROR(INDEX(BANK_CLEAN!$A$2:$A$1001,MATCH(MINIFS(BANK_CLEAN!$J$2:$J$1001,BANK_CLEAN!$H$2:$H$1001,G6,BANK_CLEAN!$L$2:$L$1001,""),BANK_CLEAN!$J$2:$J$1001,0)),"")) | I6: =IF(H6="","",INDEX(BANK_CLEAN!$B$2:$B$1001,H6)) | J6: =IF(H6="","",IF(F6="OUT",INDEX(BANK_CLEAN!$F$2:$F$1001,H6),INDEX(BANK_CLEAN!$E$2:$E$1001,H6))) | K6: =IF(H6="","",ABS(E6-J6)) | L6: =IF(OR(H6="",B6="",I6=""),"",ABS(B6-I6)) | M6: =IF(H6="",0,LET(pct,IF(E6>0,K6/E6,1),days,IFERROR(L6,999),100-pct*200-days*3)) | N6: =IF(A6="","",IF(H6="","Unmatched GL",IF(AND(K6<=Tol_Amount,L6<=Tol_Days),"Matched",IF(M6>Tol_NearPct,"Near Match","Unmatched GL"))))
A7: =IF(GL_CLEAN!A7="","",GL_CLEAN!A7) | B7: =IF(A7="","",GL_CLEAN!B7) | C7: =IF(A7="","",GL_CLEAN!C7) | D7: =IF(A7="","",GL_CLEAN!H7) | E7: =IF(A7="","",GL_CLEAN!I7) | F7: =IF(A7="","",GL_CLEAN!J7) | G7: =IF(A7="","",IF(F7="OUT","DR","CR")) | H7: =IF(A7="","",IFERROR(INDEX(BANK_CLEAN!$A$2:$A$1001,MATCH(MINIFS(BANK_CLEAN!$J$2:$J$1001,BANK_CLEAN!$H$2:$H$1001,G7,BANK_CLEAN!$L$2:$L$1001,""),BANK_CLEAN!$J$2:$J$1001,0)),"")) | I7: =IF(H7="","",INDEX(BANK_CLEAN!$B$2:$B$1001,H7)) | J7: =IF(H7="","",IF(F7="OUT",INDEX(BANK_CLEAN!$F$2:$F$1001,H7),INDEX(BANK_CLEAN!$E$2:$E$1001,H7))) | K7: =IF(H7="","",ABS(E7-J7)) | L7: =IF(OR(H7="",B7="",I7=""),"",ABS(B7-I7)) | M7: =IF(H7="",0,LET(pct,IF(E7>0,K7/E7,1),days,IFERROR(L7,999),100-pct*200-days*3)) | N7: =IF(A7="","",IF(H7="","Unmatched GL",IF(AND(K7<=Tol_Amount,L7<=Tol_Days),"Matched",IF(M7>Tol_NearPct,"Near Match","Unmatched GL"))))
A8: =IF(GL_CLEAN!A8="","",GL_CLEAN!A8) | B8: =IF(A8="","",GL_CLEAN!B8) | C8: =IF(A8="","",GL_CLEAN!C8) | D8: =IF(A8="","",GL_CLEAN!H8) | E8: =IF(A8="","",GL_CLEAN!I8) | F8: =IF(A8="","",GL_CLEAN!J8) | G8: =IF(A8="","",IF(F8="OUT","DR","CR")) | H8: =IF(A8="","",IFERROR(INDEX(BANK_CLEAN!$A$2:$A$1001,MATCH(MINIFS(BANK_CLEAN!$J$2:$J$1001,BANK_CLEAN!$H$2:$H$1001,G8,BANK_CLEAN!$L$2:$L$1001,""),BANK_CLEAN!$J$2:$J$1001,0)),"")) | I8: =IF(H8="","",INDEX(BANK_CLEAN!$B$2:$B$1001,H8)) | J8: =IF(H8="","",IF(F8="OUT",INDEX(BANK_CLEAN!$F$2:$F$1001,H8),INDEX(BANK_CLEAN!$E$2:$E$1001,H8))) | K8: =IF(H8="","",ABS(E8-J8)) | L8: =IF(OR(H8="",B8="",I8=""),"",ABS(B8-I8)) | M8: =IF(H8="",0,LET(pct,IF(E8>0,K8/E8,1),days,IFERROR(L8,999),100-pct*200-days*3)) | N8: =IF(A8="","",IF(H8="","Unmatched GL",IF(AND(K8<=Tol_Amount,L8<=Tol_Days),"Matched",IF(M8>Tol_NearPct,"Near Match","Unmatched GL"))))
A9: =IF(GL_CLEAN!A9="","",GL_CLEAN!A9) | B9: =IF(A9="","",GL_CLEAN!B9) | C9: =IF(A9="","",GL_CLEAN!C9) | D9: =IF(A9="","",GL_CLEAN!H9) | E9: =IF(A9="","",GL_CLEAN!I9) | F9: =IF(A9="","",GL_CLEAN!J9) | G9: =IF(A9="","",IF(F9="OUT","DR","CR")) | H9: =IF(A9="","",IFERROR(INDEX(BANK_CLEAN!$A$2:$A$1001,MATCH(MINIFS(BANK_CLEAN!$J$2:$J$1001,BANK_CLEAN!$H$2:$H$1001,G9,BANK_CLEAN!$L$2:$L$1001,""),BANK_CLEAN!$J$2:$J$1001,0)),"")) | I9: =IF(H9="","",INDEX(BANK_CLEAN!$B$2:$B$1001,H9)) | J9: =IF(H9="","",IF(F9="OUT",INDEX(BANK_CLEAN!$F$2:$F$1001,H9),INDEX(BANK_CLEAN!$E$2:$E$1001,H9))) | K9: =IF(H9="","",ABS(E9-J9)) | L9: =IF(OR(H9="",B9="",I9=""),"",ABS(B9-I9)) | M9: =IF(H9="",0,LET(pct,IF(E9>0,K9/E9,1),days,IFERROR(L9,999),100-pct*200-days*3)) | N9: =IF(A9="","",IF(H9="","Unmatched GL",IF(AND(K9<=Tol_Amount,L9<=Tol_Days),"Matched",IF(M9>Tol_NearPct,"Near Match","Unmatched GL"))))
A10: =IF(GL_CLEAN!A10="","",GL_CLEAN!A10) | B10: =IF(A10="","",GL_CLEAN!B10) | C10: =IF(A10="","",GL_CLEAN!C10) | D10: =IF(A10="","",GL_CLEAN!H10) | E10: =IF(A10="","",GL_CLEAN!I10) | F10: =IF(A10="","",GL_CLEAN!J10) | G10: =IF(A10="","",IF(F10="OUT","DR","CR")) | H10: =IF(A10="","",IFERROR(INDEX(BANK_CLEAN!$A$2:$A$1001,MATCH(MINIFS(BANK_CLEAN!$J$2:$J$1001,BANK_CLEAN!$H$2:$H$1001,G10,BANK_CLEAN!$L$2:$L$1001,""),BANK_CLEAN!$J$2:$J$1001,0)),"")) | I10: =IF(H10="","",INDEX(BANK_CLEAN!$B$2:$B$1001,H10)) | J10: =IF(H10="","",IF(F10="OUT",INDEX(BANK_CLEAN!$F$2:$F$1001,H10),INDEX(BANK_CLEAN!$E$2:$E$1001,H10))) | K10: =IF(H10="","",ABS(E10-J10)) | L10: =IF(OR(H10="",B10="",I10=""),"",ABS(B10-I10)) | M10: =IF(H10="",0,LET(pct,IF(E10>0,K10/E10,1),days,IFERROR(L10,999),100-pct*200-days*3)) | N10: =IF(A10="","",IF(H10="","Unmatched GL",IF(AND(K10<=Tol_Amount,L10<=Tol_Days),"Matched",IF(M10>Tol_NearPct,"Near Match","Unmatched GL"))))
A11: =IF(GL_CLEAN!A11="","",GL_CLEAN!A11) | B11: =IF(A11="","",GL_CLEAN!B11) | C11: =IF(A11="","",GL_CLEAN!C11) | D11: =IF(A11="","",GL_CLEAN!H11) | E11: =IF(A11="","",GL_CLEAN!I11) | F11: =IF(A11="","",GL_CLEAN!J11) | G11: =IF(A11="","",IF(F11="OUT","DR","CR")) | H11: =IF(A11="","",IFERROR(INDEX(BANK_CLEAN!$A$2:$A$1001,MATCH(MINIFS(BANK_CLEAN!$J$2:$J$1001,BANK_CLEAN!$H$2:$H$1001,G11,BANK_CLEAN!$L$2:$L$1001,""),BANK_CLEAN!$J$2:$J$1001,0)),"")) | I11: =IF(H11="","",INDEX(BANK_CLEAN!$B$2:$B$1001,H11)) | J11: =IF(H11="","",IF(F11="OUT",INDEX(BANK_CLEAN!$F$2:$F$1001,H11),INDEX(BANK_CLEAN!$E$2:$E$1001,H11))) | K11: =IF(H11="","",ABS(E11-J11)) | L11: =IF(OR(H11="",B11="",I11=""),"",ABS(B11-I11)) | M11: =IF(H11="",0,LET(pct,IF(E11>0,K11/E11,1),days,IFERROR(L11,999),100-pct*200-days*3)) | N11: =IF(A11="","",IF(H11="","Unmatched GL",IF(AND(K11<=Tol_Amount,L11<=Tol_Days),"Matched",IF(M11>Tol_NearPct,"Near Match","Unmatched GL"))))
A12: =IF(GL_CLEAN!A12="","",GL_CLEAN!A12) | B12: =IF(A12="","",GL_CLEAN!B12) | C12: =IF(A12="","",GL_CLEAN!C12) | D12: =IF(A12="","",GL_CLEAN!H12) | E12: =IF(A12="","",GL_CLEAN!I12) | F12: =IF(A12="","",GL_CLEAN!J12) | G12: =IF(A12="","",IF(F12="OUT","DR","CR")) | H12: =IF(A12="","",IFERROR(INDEX(BANK_CLEAN!$A$2:$A$1001,MATCH(MINIFS(BANK_CLEAN!$J$2:$J$1001,BANK_CLEAN!$H$2:$H$1001,G12,BANK_CLEAN!$L$2:$L$1001,""),BANK_CLEAN!$J$2:$J$1001,0)),"")) | I12: =IF(H12="","",INDEX(BANK_CLEAN!$B$2:$B$1001,H12)) | J12: =IF(H12="","",IF(F12="OUT",INDEX(BANK_CLEAN!$F$2:$F$1001,H12),INDEX(BANK_CLEAN!$E$2:$E$1001,H12))) | K12: =IF(H12="","",ABS(E12-J12)) | L12: =IF(OR(H12="",B12="",I12=""),"",ABS(B12-I12)) | M12: =IF(H12="",0,LET(pct,IF(E12>0,K12/E12,1),days,IFERROR(L12,999),100-pct*200-days*3)) | N12: =IF(A12="","",IF(H12="","Unmatched GL",IF(AND(K12<=Tol_Amount,L12<=Tol_Days),"Matched",IF(M12>Tol_NearPct,"Near Match","Unmatched GL"))))
A13: =IF(GL_CLEAN!A13="","",GL_CLEAN!A13) | B13: =IF(A13="","",GL_CLEAN!B13) | C13: =IF(A13="","",GL_CLEAN!C13) | D13: =IF(A13="","",GL_CLEAN!H13) | E13: =IF(A13="","",GL_CLEAN!I13) | F13: =IF(A13="","",GL_CLEAN!J13) | G13: =IF(A13="","",IF(F13="OUT","DR","CR")) | H13: =IF(A13="","",IFERROR(INDEX(BANK_CLEAN!$A$2:$A$1001,MATCH(MINIFS(BANK_CLEAN!$J$2:$J$1001,BANK_CLEAN!$H$2:$H$1001,G13,BANK_CLEAN!$L$2:$L$1001,""),BANK_CLEAN!$J$2:$J$1001,0)),"")) | I13: =IF(H13="","",INDEX(BANK_CLEAN!$B$2:$B$1001,H13)) | J13: =IF(H13="","",IF(F13="OUT",INDEX(BANK_CLEAN!$F$2:$F$1001,H13),INDEX(BANK_CLEAN!$E$2:$E$1001,H13))) | K13: =IF(H13="","",ABS(E13-J13)) | L13: =IF(OR(H13="",B13="",I13=""),"",ABS(B13-I13)) | M13: =IF(H13="",0,LET(pct,IF(E13>0,K13/E13,1),days,IFERROR(L13,999),100-pct*200-days*3)) | N13: =IF(A13="","",IF(H13="","Unmatched GL",IF(AND(K13<=Tol_Amount,L13<=Tol_Days),"Matched",IF(M13>Tol_NearPct,"Near Match","Unmatched GL"))))
... A1001: =IF(GL_CLEAN!A1001="","",GL_CLEAN!A1001) | B1001: =IF(A1001="","",GL_CLEAN!B1001) | C1001: =IF(A1001="","",GL_CLEAN!C1001) | D1001: =IF(A1001="","",GL_CLEAN!H1001) | E1001: =IF(A1001="","",GL_CLEAN!I1001) | F1001: =IF(A1001="","",GL_CLEAN!J1001) | G1001: =IF(A1001="","",IF(F1001="OUT","DR","CR")) | H1001: =IF(A1001="","",IFERROR(INDEX(BANK_CLEAN!$A$2:$A$1001,MATCH(MINIFS(BANK_CLEAN!$J$2:$J$1001,BANK_CLEAN!$H$2:$H$1001,G1001,BANK_CLEAN!$L$2:$L$1001,""),BANK_CLEAN!$J$2:$J$1001,0)),"")) | I1001: =IF(H1001="","",INDEX(BANK_CLEAN!$B$2:$B$1001,H1001)) | J1001: =IF(H1001="","",IF(F1001="OUT",INDEX(BANK_CLEAN!$F$2:$F$1001,H1001),INDEX(BANK_CLEAN!$E$2:$E$1001,H1001))) | K1001: =IF(H1001="","",ABS(E1001-J1001)) | L1001: =IF(OR(H1001="",B1001="",I1001=""),"",ABS(B1001-I1001)) | M1001: =IF(H1001="",0,LET(pct,IF(E1001>0,K1001/E1001,1),days,IFERROR(L1001,999),100-pct*200-days*3)) | N1001: =IF(A1001="","",IF(H1001="","Unmatched GL",IF(AND(K1001<=Tol_Amount,L1001<=Tol_Days),"Matched",IF(M1001>Tol_NearPct,"Near Match","Unmatched GL"))))

Sheet RECON_RESULTS
A1: الحالة Status | B1: رقم القيد GL JE | C1: تاريخ GL GL Date | D1: مبلغ GL GL Amount | E1: الاتجاه Direction | F1: تاريخ البنك Bank Date | G1: الدائن Bank Credit | H1: المدين Bank Debit | I1: مبلغ البنك Bank Amount | J1: الفرق Difference | K1: الأيام Days Apart | L1: نسبة التطابق Score | M1: الحساب GL Account | N1: اسم الحساب GL Name | O1: وصف البنك Bank Desc | P1: ملاحظات المراجع Reviewer Notes
A2: =IF(MATCH_ENGINE!A2="","",MATCH_ENGINE!N2) | B2: =IF(MATCH_ENGINE!A2="","",MATCH_ENGINE!C2) | C2: =IF(MATCH_ENGINE!A2="","",MATCH_ENGINE!B2) | D2: =IF(MATCH_ENGINE!A2="","",MATCH_ENGINE!D2) | E2: =IF(MATCH_ENGINE!A2="","",MATCH_ENGINE!F2) | F2: =IF(MATCH_ENGINE!A2="","",MATCH_ENGINE!I2) | G2: =IF(MATCH_ENGINE!H2="","",IF(MATCH_ENGINE!F2="IN",MATCH_ENGINE!J2,"")) | H2: =IF(MATCH_ENGINE!H2="","",IF(MATCH_ENGINE!F2="OUT",MATCH_ENGINE!J2,"")) | I2: =IF(MATCH_ENGINE!H2="","",MATCH_ENGINE!J2) | J2: =IF(MATCH_ENGINE!A2="","",MATCH_ENGINE!K2) | K2: =IF(MATCH_ENGINE!A2="","",MATCH_ENGINE!L2) | L2: =IF(MATCH_ENGINE!A2="","",MATCH_ENGINE!M2) | M2: =IF(MATCH_ENGINE!A2="","",GL_CLEAN!F2) | N2: =IF(MATCH_ENGINE!A2="","",GL_CLEAN!G2) | O2: =IF(MATCH_ENGINE!H2="","",INDEX(BANK_CLEAN!$C$2:$C$1001,MATCH_ENGINE!H2))
A3: =IF(MATCH_ENGINE!A3="","",MATCH_ENGINE!N3) | B3: =IF(MATCH_ENGINE!A3="","",MATCH_ENGINE!C3) | C3: =IF(MATCH_ENGINE!A3="","",MATCH_ENGINE!B3) | D3: =IF(MATCH_ENGINE!A3="","",MATCH_ENGINE!D3) | E3: =IF(MATCH_ENGINE!A3="","",MATCH_ENGINE!F3) | F3: =IF(MATCH_ENGINE!A3="","",MATCH_ENGINE!I3) | G3: =IF(MATCH_ENGINE!H3="","",IF(MATCH_ENGINE!F3="IN",MATCH_ENGINE!J3,"")) | H3: =IF(MATCH_ENGINE!H3="","",IF(MATCH_ENGINE!F3="OUT",MATCH_ENGINE!J3,"")) | I3: =IF(MATCH_ENGINE!H3="","",MATCH_ENGINE!J3) | J3: =IF(MATCH_ENGINE!A3="","",MATCH_ENGINE!K3) | K3: =IF(MATCH_ENGINE!A3="","",MATCH_ENGINE!L3) | L3: =IF(MATCH_ENGINE!A3="","",MATCH_ENGINE!M3) | M3: =IF(MATCH_ENGINE!A3="","",GL_CLEAN!F3) | N3: =IF(MATCH_ENGINE!A3="","",GL_CLEAN!G3) | O3: =IF(MATCH_ENGINE!H3="","",INDEX(BANK_CLEAN!$C$2:$C$1001,MATCH_ENGINE!H3))
A4: =IF(MATCH_ENGINE!A4="","",MATCH_ENGINE!N4) | B4: =IF(MATCH_ENGINE!A4="","",MATCH_ENGINE!C4) | C4: =IF(MATCH_ENGINE!A4="","",MATCH_ENGINE!B4) | D4: =IF(MATCH_ENGINE!A4="","",MATCH_ENGINE!D4) | E4: =IF(MATCH_ENGINE!A4="","",MATCH_ENGINE!F4) | F4: =IF(MATCH_ENGINE!A4="","",MATCH_ENGINE!I4) | G4: =IF(MATCH_ENGINE!H4="","",IF(MATCH_ENGINE!F4="IN",MATCH_ENGINE!J4,"")) | H4: =IF(MATCH_ENGINE!H4="","",IF(MATCH_ENGINE!F4="OUT",MATCH_ENGINE!J4,"")) | I4: =IF(MATCH_ENGINE!H4="","",MATCH_ENGINE!J4) | J4: =IF(MATCH_ENGINE!A4="","",MATCH_ENGINE!K4) | K4: =IF(MATCH_ENGINE!A4="","",MATCH_ENGINE!L4) | L4: =IF(MATCH_ENGINE!A4="","",MATCH_ENGINE!M4) | M4: =IF(MATCH_ENGINE!A4="","",GL_CLEAN!F4) | N4: =IF(MATCH_ENGINE!A4="","",GL_CLEAN!G4) | O4: =IF(MATCH_ENGINE!H4="","",INDEX(BANK_CLEAN!$C$2:$C$1001,MATCH_ENGINE!H4))
A5: =IF(MATCH_ENGINE!A5="","",MATCH_ENGINE!N5) | B5: =IF(MATCH_ENGINE!A5="","",MATCH_ENGINE!C5) | C5: =IF(MATCH_ENGINE!A5="","",MATCH_ENGINE!B5) | D5: =IF(MATCH_ENGINE!A5="","",MATCH_ENGINE!D5) | E5: =IF(MATCH_ENGINE!A5="","",MATCH_ENGINE!F5) | F5: =IF(MATCH_ENGINE!A5="","",MATCH_ENGINE!I5) | G5: =IF(MATCH_ENGINE!H5="","",IF(MATCH_ENGINE!F5="IN",MATCH_ENGINE!J5,"")) | H5: =IF(MATCH_ENGINE!H5="","",IF(MATCH_ENGINE!F5="OUT",MATCH_ENGINE!J5,"")) | I5: =IF(MATCH_ENGINE!H5="","",MATCH_ENGINE!J5) | J5: =IF(MATCH_ENGINE!A5="","",MATCH_ENGINE!K5) | K5: =IF(MATCH_ENGINE!A5="","",MATCH_ENGINE!L5) | L5: =IF(MATCH_ENGINE!A5="","",MATCH_ENGINE!M5) | M5: =IF(MATCH_ENGINE!A5="","",GL_CLEAN!F5) | N5: =IF(MATCH_ENGINE!A5="","",GL_CLEAN!G5) | O5: =IF(MATCH_ENGINE!H5="","",INDEX(BANK_CLEAN!$C$2:$C$1001,MATCH_ENGINE!H5))
A6: =IF(MATCH_ENGINE!A6="","",MATCH_ENGINE!N6) | B6: =IF(MATCH_ENGINE!A6="","",MATCH_ENGINE!C6) | C6: =IF(MATCH_ENGINE!A6="","",MATCH_ENGINE!B6) | D6: =IF(MATCH_ENGINE!A6="","",MATCH_ENGINE!D6) | E6: =IF(MATCH_ENGINE!A6="","",MATCH_ENGINE!F6) | F6: =IF(MATCH_ENGINE!A6="","",MATCH_ENGINE!I6) | G6: =IF(MATCH_ENGINE!H6="","",IF(MATCH_ENGINE!F6="IN",MATCH_ENGINE!J6,"")) | H6: =IF(MATCH_ENGINE!H6="","",IF(MATCH_ENGINE!F6="OUT",MATCH_ENGINE!J6,"")) | I6: =IF(MATCH_ENGINE!H6="","",MATCH_ENGINE!J6) | J6: =IF(MATCH_ENGINE!A6="","",MATCH_ENGINE!K6) | K6: =IF(MATCH_ENGINE!A6="","",MATCH_ENGINE!L6) | L6: =IF(MATCH_ENGINE!A6="","",MATCH_ENGINE!M6) | M6: =IF(MATCH_ENGINE!A6="","",GL_CLEAN!F6) | N6: =IF(MATCH_ENGINE!A6="","",GL_CLEAN!G6) | O6: =IF(MATCH_ENGINE!H6="","",INDEX(BANK_CLEAN!$C$2:$C$1001,MATCH_ENGINE!H6))
A7: =IF(MATCH_ENGINE!A7="","",MATCH_ENGINE!N7) | B7: =IF(MATCH_ENGINE!A7="","",MATCH_ENGINE!C7) | C7: =IF(MATCH_ENGINE!A7="","",MATCH_ENGINE!B7) | D7: =IF(MATCH_ENGINE!A7="","",MATCH_ENGINE!D7) | E7: =IF(MATCH_ENGINE!A7="","",MATCH_ENGINE!F7) | F7: =IF(MATCH_ENGINE!A7="","",MATCH_ENGINE!I7) | G7: =IF(MATCH_ENGINE!H7="","",IF(MATCH_ENGINE!F7="IN",MATCH_ENGINE!J7,"")) | H7: =IF(MATCH_ENGINE!H7="","",IF(MATCH_ENGINE!F7="OUT",MATCH_ENGINE!J7,"")) | I7: =IF(MATCH_ENGINE!H7="","",MATCH_ENGINE!J7) | J7: =IF(MATCH_ENGINE!A7="","",MATCH_ENGINE!K7) | K7: =IF(MATCH_ENGINE!A7="","",MATCH_ENGINE!L7) | L7: =IF(MATCH_ENGINE!A7="","",MATCH_ENGINE!M7) | M7: =IF(MATCH_ENGINE!A7="","",GL_CLEAN!F7) | N7: =IF(MATCH_ENGINE!A7="","",GL_CLEAN!G7) | O7: =IF(MATCH_ENGINE!H7="","",INDEX(BANK_CLEAN!$C$2:$C$1001,MATCH_ENGINE!H7))
A8: =IF(MATCH_ENGINE!A8="","",MATCH_ENGINE!N8) | B8: =IF(MATCH_ENGINE!A8="","",MATCH_ENGINE!C8) | C8: =IF(MATCH_ENGINE!A8="","",MATCH_ENGINE!B8) | D8: =IF(MATCH_ENGINE!A8="","",MATCH_ENGINE!D8) | E8: =IF(MATCH_ENGINE!A8="","",MATCH_ENGINE!F8) | F8: =IF(MATCH_ENGINE!A8="","",MATCH_ENGINE!I8) | G8: =IF(MATCH_ENGINE!H8="","",IF(MATCH_ENGINE!F8="IN",MATCH_ENGINE!J8,"")) | H8: =IF(MATCH_ENGINE!H8="","",IF(MATCH_ENGINE!F8="OUT",MATCH_ENGINE!J8,"")) | I8: =IF(MATCH_ENGINE!H8="","",MATCH_ENGINE!J8) | J8: =IF(MATCH_ENGINE!A8="","",MATCH_ENGINE!K8) | K8: =IF(MATCH_ENGINE!A8="","",MATCH_ENGINE!L8) | L8: =IF(MATCH_ENGINE!A8="","",MATCH_ENGINE!M8) | M8: =IF(MATCH_ENGINE!A8="","",GL_CLEAN!F8) | N8: =IF(MATCH_ENGINE!A8="","",GL_CLEAN!G8) | O8: =IF(MATCH_ENGINE!H8="","",INDEX(BANK_CLEAN!$C$2:$C$1001,MATCH_ENGINE!H8))
A9: =IF(MATCH_ENGINE!A9="","",MATCH_ENGINE!N9) | B9: =IF(MATCH_ENGINE!A9="","",MATCH_ENGINE!C9) | C9: =IF(MATCH_ENGINE!A9="","",MATCH_ENGINE!B9) | D9: =IF(MATCH_ENGINE!A9="","",MATCH_ENGINE!D9) | E9: =IF(MATCH_ENGINE!A9="","",MATCH_ENGINE!F9) | F9: =IF(MATCH_ENGINE!A9="","",MATCH_ENGINE!I9) | G9: =IF(MATCH_ENGINE!H9="","",IF(MATCH_ENGINE!F9="IN",MATCH_ENGINE!J9,"")) | H9: =IF(MATCH_ENGINE!H9="","",IF(MATCH_ENGINE!F9="OUT",MATCH_ENGINE!J9,"")) | I9: =IF(MATCH_ENGINE!H9="","",MATCH_ENGINE!J9) | J9: =IF(MATCH_ENGINE!A9="","",MATCH_ENGINE!K9) | K9: =IF(MATCH_ENGINE!A9="","",MATCH_ENGINE!L9) | L9: =IF(MATCH_ENGINE!A9="","",MATCH_ENGINE!M9) | M9: =IF(MATCH_ENGINE!A9="","",GL_CLEAN!F9) | N9: =IF(MATCH_ENGINE!A9="","",GL_CLEAN!G9) | O9: =IF(MATCH_ENGINE!H9="","",INDEX(BANK_CLEAN!$C$2:$C$1001,MATCH_ENGINE!H9))
A10: =IF(MATCH_ENGINE!A10="","",MATCH_ENGINE!N10) | B10: =IF(MATCH_ENGINE!A10="","",MATCH_ENGINE!C10) | C10: =IF(MATCH_ENGINE!A10="","",MATCH_ENGINE!B10) | D10: =IF(MATCH_ENGINE!A10="","",MATCH_ENGINE!D10) | E10: =IF(MATCH_ENGINE!A10="","",MATCH_ENGINE!F10) | F10: =IF(MATCH_ENGINE!A10="","",MATCH_ENGINE!I10) | G10: =IF(MATCH_ENGINE!H10="","",IF(MATCH_ENGINE!F10="IN",MATCH_ENGINE!J10,"")) | H10: =IF(MATCH_ENGINE!H10="","",IF(MATCH_ENGINE!F10="OUT",MATCH_ENGINE!J10,"")) | I10: =IF(MATCH_ENGINE!H10="","",MATCH_ENGINE!J10) | J10: =IF(MATCH_ENGINE!A10="","",MATCH_ENGINE!K10) | K10: =IF(MATCH_ENGINE!A10="","",MATCH_ENGINE!L10) | L10: =IF(MATCH_ENGINE!A10="","",MATCH_ENGINE!M10) | M10: =IF(MATCH_ENGINE!A10="","",GL_CLEAN!F10) | N10: =IF(MATCH_ENGINE!A10="","",GL_CLEAN!G10) | O10: =IF(MATCH_ENGINE!H10="","",INDEX(BANK_CLEAN!$C$2:$C$1001,MATCH_ENGINE!H10))
A11: =IF(MATCH_ENGINE!A11="","",MATCH_ENGINE!N11) | B11: =IF(MATCH_ENGINE!A11="","",MATCH_ENGINE!C11) | C11: =IF(MATCH_ENGINE!A11="","",MATCH_ENGINE!B11) | D11: =IF(MATCH_ENGINE!A11="","",MATCH_ENGINE!D11) | E11: =IF(MATCH_ENGINE!A11="","",MATCH_ENGINE!F11) | F11: =IF(MATCH_ENGINE!A11="","",MATCH_ENGINE!I11) | G11: =IF(MATCH_ENGINE!H11="","",IF(MATCH_ENGINE!F11="IN",MATCH_ENGINE!J11,"")) | H11: =IF(MATCH_ENGINE!H11="","",IF(MATCH_ENGINE!F11="OUT",MATCH_ENGINE!J11,"")) | I11: =IF(MATCH_ENGINE!H11="","",MATCH_ENGINE!J11) | J11: =IF(MATCH_ENGINE!A11="","",MATCH_ENGINE!K11) | K11: =IF(MATCH_ENGINE!A11="","",MATCH_ENGINE!L11) | L11: =IF(MATCH_ENGINE!A11="","",MATCH_ENGINE!M11) | M11: =IF(MATCH_ENGINE!A11="","",GL_CLEAN!F11) | N11: =IF(MATCH_ENGINE!A11="","",GL_CLEAN!G11) | O11: =IF(MATCH_ENGINE!H11="","",INDEX(BANK_CLEAN!$C$2:$C$1001,MATCH_ENGINE!H11))
A12: =IF(MATCH_ENGINE!A12="","",MATCH_ENGINE!N12) | B12: =IF(MATCH_ENGINE!A12="","",MATCH_ENGINE!C12) | C12: =IF(MATCH_ENGINE!A12="","",MATCH_ENGINE!B12) | D12: =IF(MATCH_ENGINE!A12="","",MATCH_ENGINE!D12) | E12: =IF(MATCH_ENGINE!A12="","",MATCH_ENGINE!F12) | F12: =IF(MATCH_ENGINE!A12="","",MATCH_ENGINE!I12) | G12: =IF(MATCH_ENGINE!H12="","",IF(MATCH_ENGINE!F12="IN",MATCH_ENGINE!J12,"")) | H12: =IF(MATCH_ENGINE!H12="","",IF(MATCH_ENGINE!F12="OUT",MATCH_ENGINE!J12,"")) | I12: =IF(MATCH_ENGINE!H12="","",MATCH_ENGINE!J12) | J12: =IF(MATCH_ENGINE!A12="","",MATCH_ENGINE!K12) | K12: =IF(MATCH_ENGINE!A12="","",MATCH_ENGINE!L12) | L12: =IF(MATCH_ENGINE!A12="","",MATCH_ENGINE!M12) | M12: =IF(MATCH_ENGINE!A12="","",GL_CLEAN!F12) | N12: =IF(MATCH_ENGINE!A12="","",GL_CLEAN!G12) | O12: =IF(MATCH_ENGINE!H12="","",INDEX(BANK_CLEAN!$C$2:$C$1001,MATCH_ENGINE!H12))
A13: =IF(MATCH_ENGINE!A13="","",MATCH_ENGINE!N13) | B13: =IF(MATCH_ENGINE!A13="","",MATCH_ENGINE!C13) | C13: =IF(MATCH_ENGINE!A13="","",MATCH_ENGINE!B13) | D13: =IF(MATCH_ENGINE!A13="","",MATCH_ENGINE!D13) | E13: =IF(MATCH_ENGINE!A13="","",MATCH_ENGINE!F13) | F13: =IF(MATCH_ENGINE!A13="","",MATCH_ENGINE!I13) | G13: =IF(MATCH_ENGINE!H13="","",IF(MATCH_ENGINE!F13="IN",MATCH_ENGINE!J13,"")) | H13: =IF(MATCH_ENGINE!H13="","",IF(MATCH_ENGINE!F13="OUT",MATCH_ENGINE!J13,"")) | I13: =IF(MATCH_ENGINE!H13="","",MATCH_ENGINE!J13) | J13: =IF(MATCH_ENGINE!A13="","",MATCH_ENGINE!K13) | K13: =IF(MATCH_ENGINE!A13="","",MATCH_ENGINE!L13) | L13: =IF(MATCH_ENGINE!A13="","",MATCH_ENGINE!M13) | M13: =IF(MATCH_ENGINE!A13="","",GL_CLEAN!F13) | N13: =IF(MATCH_ENGINE!A13="","",GL_CLEAN!G13) | O13: =IF(MATCH_ENGINE!H13="","",INDEX(BANK_CLEAN!$C$2:$C$1001,MATCH_ENGINE!H13))
... A1001: =IF(MATCH_ENGINE!A1001="","",MATCH_ENGINE!N1001) | B1001: =IF(MATCH_ENGINE!A1001="","",MATCH_ENGINE!C1001) | C1001: =IF(MATCH_ENGINE!A1001="","",MATCH_ENGINE!B1001) | D1001: =IF(MATCH_ENGINE!A1001="","",MATCH_ENGINE!D1001) | E1001: =IF(MATCH_ENGINE!A1001="","",MATCH_ENGINE!F1001) | F1001: =IF(MATCH_ENGINE!A1001="","",MATCH_ENGINE!I1001) | G1001: =IF(MATCH_ENGINE!H1001="","",IF(MATCH_ENGINE!F1001="IN",MATCH_ENGINE!J1001,"")) | H1001: =IF(MATCH_ENGINE!H1001="","",IF(MATCH_ENGINE!F1001="OUT",MATCH_ENGINE!J1001,"")) | I1001: =IF(MATCH_ENGINE!H1001="","",MATCH_ENGINE!J1001) | J1001: =IF(MATCH_ENGINE!A1001="","",MATCH_ENGINE!K1001) | K1001: =IF(MATCH_ENGINE!A1001="","",MATCH_ENGINE!L1001) | L1001: =IF(MATCH_ENGINE!A1001="","",MATCH_ENGINE!M1001) | M1001: =IF(MATCH_ENGINE!A1001="","",GL_CLEAN!F1001) | N1001: =IF(MATCH_ENGINE!A1001="","",GL_CLEAN!G1001) | O1001: =IF(MATCH_ENGINE!H1001="","",INDEX(BANK_CLEAN!$C$2:$C$1001,MATCH_ENGINE!H1001))

Sheet DASHBOARD
B2: =Co_Name | E2: تقرير مطابقة الحسابات البنكية
E3: =Co_BankName&" — "&Co_IBAN&" — "&Rpt_Period
B6: مؤشرات الأداء الرئيسية — KEY PERFORMANCE INDICATORS
B7: معدل المطابقة | C7: مطابق | D7: قريب | E7: GL غير مطابق | F7: بنك غير مطابق | G7: إجمالي الاستثناءات
B8: MATCH RATE | C8: MATCHED | D8: NEAR MATCH | E8: UNMATCHED GL | F8: UNMATCHED BANK | G8: EXCEPTIONS
B9: =IFERROR((COUNTIF(MATCH_ENGINE!N$2:N$1001,"Matched")+COUNTIF(MATCH_ENGINE!N$2:N$1001,"Near Match"))/COUNTIF(MATCH_ENGINE!N$2:N$1001,"<>"),0) | C9: =COUNTIF(MATCH_ENGINE!N$2:N$1001,"Matched") | D9: =COUNTIF(MATCH_ENGINE!N$2:N$1001,"Near Match") | E9: =COUNTIF(MATCH_ENGINE!N$2:N$1001,"Unmatched GL") | F9: =COUNTIFS(BANK_CLEAN!A$2:A$1001,"<>",BANK_CLEAN!L$2:L$1001,"")-COUNTIF(BANK_CLEAN!A$2:A$1001,"") | G9: =COUNTIF(MATCH_ENGINE!N$2:N$1001,"Unmatched GL")+COUNTIF(MATCH_ENGINE!N$2:N$1001,"Near Match")
B12: بيان التوفيق — RECONCILIATION WATERFALL
B13: =SUMPRODUCT((BANK_CLEAN!A$2:A$1001<>"")*BANK_CLEAN!E$2:E$1001) | C13: الدائن البنكي | D13: Bank Credit
B14: =SUMPRODUCT((BANK_CLEAN!A$2:A$1001<>"")*BANK_CLEAN!F$2:F$1001) | C14: ناقص: المدين البنكي | D14: Less: Bank Debit
B15: =B14-B15 | C15: صافي حركة البنك | D15: Net Bank Movement
B16: =SUMPRODUCT((GL_CLEAN!J$2:J$1001="IN")*(GL_CLEAN!A$2:A$1001<>"")*GL_CLEAN!H$2:H$1001) | C16: GL الوارد | D16: GL Inward
B17: =SUMPRODUCT((GL_CLEAN!J$2:J$1001="OUT")*(GL_CLEAN!A$2:A$1001<>"")*ABS(GL_CLEAN!H$2:H$1001)) | C17: ناقص: GL الصادر | D17: GL Outward
B18: =B17-B18 | C18: صافي حركة GL | D18: Net GL Movement
B19: =ABS(B16-B19) | C19: الفرق (بنك - GL) | D19: Difference
B22: ملخص الحالات — STATUS SUMMARY
B23: =COUNTIF(MATCH_ENGINE!N$2:N$1001,"Matched") | C23: =COUNTIF(MATCH_ENGINE!N$2:N$1001,"Near Match") | D23: =COUNTIF(MATCH_ENGINE!N$2:N$1001,"Unmatched GL") | E23: =COUNTIFS(BANK_CLEAN!A$2:A$1001,"<>",BANK_CLEAN!L$2:L$1001,"")-COUNTIF(BANK_CLEAN!A$2:A$1001,"")
B24: مطابق | C24: قريب | D24: GL غير مطابق | E24: بنك غير مطابق
B25: MATCHED | C25: NEAR MATCH | D25: UNMATCHED GL | E25: UNMATCHED BANK
B28: التعرض للاستثناءات — EXCEPTION EXPOSURE
B29: =SUMPRODUCT((RECON_RESULTS!A$2:A$1001="Unmatched Bank")*(RECON_RESULTS!I$2:I$1001)) | C29: إجمالي البنك غير المطابق | D29: Unmatched Bank Value
B30: =SUMPRODUCT((RECON_RESULTS!A$2:A$1001="Unmatched GL")*ABS(RECON_RESULTS!D$2:D$1001)) | C30: إجمالي GL غير المطابق | D30: Unmatched GL Value
B31: =SUMPRODUCT((RECON_RESULTS!A$2:A$1001="Near Match")*RECON_RESULTS!J$2:J$1001) | C31: إجمالي المطابقات القريبة | D31: Near Match Exposure

Sheet EXCEPTIONS
B1: حركات بنكية بدون قيد GL — UNMATCHED BANK
B2: الحالة Status | C2: التاريخ Date | D2: الوصف Description | E2: الدائن Credit | F2: المدين Debit | G2: الرصيد Balance | H2: الجانب Side | I2: النوع Type | J2: حالة المراجعة Review | K2: الأولوية Priority | L2: ملاحظات Comments
B3: =IFERROR(INDEX(RECON_RESULTS!$A$2:$A$1001,SMALL(IF(RECON_RESULTS!$A$2:$A$1001="Unmatched Bank",ROW(RECON_RESULTS!$A$2:$A$1001)-1),1)),"") | C3: =IF(B3="","",INDEX(RECON_RESULTS!$F$2:$F$1001,SMALL(IF(RECON_RESULTS!$A$2:$A$1001="Unmatched Bank",ROW(RECON_RESULTS!$A$2:$A$1001)-1),1))) | D3: =IF(B3="","",INDEX(RECON_RESULTS!$O$2:$O$1001,SMALL(IF(RECON_RESULTS!$A$2:$A$1001="Unmatched Bank",ROW(RECON_RESULTS!$A$2:$A$1001)-1),1))) | E3: =IF(B3="","",INDEX(RECON_RESULTS!$G$2:$G$1001,SMALL(IF(RECON_RESULTS!$A$2:$A$1001="Unmatched Bank",ROW(RECON_RESULTS!$A$2:$A$1001)-1),1))) | F3: =IF(B3="","",INDEX(RECON_RESULTS!$H$2:$H$1001,SMALL(IF(RECON_RESULTS!$A$2:$A$1001="Unmatched Bank",ROW(RECON_RESULTS!$A$2:$A$1001)-1),1)))
B4: =IFERROR(INDEX(RECON_RESULTS!$A$2:$A$1001,SMALL(IF(RECON_RESULTS!$A$2:$A$1001="Unmatched Bank",ROW(RECON_RESULTS!$A$2:$A$1001)-1),2)),"") | C4: =IF(B4="","",INDEX(RECON_RESULTS!$F$2:$F$1001,SMALL(IF(RECON_RESULTS!$A$2:$A$1001="Unmatched Bank",ROW(RECON_RESULTS!$A$2:$A$1001)-1),2))) | D4: =IF(B4="","",INDEX(RECON_RESULTS!$O$2:$O$1001,SMALL(IF(RECON_RESULTS!$A$2:$A$1001="Unmatched Bank",ROW(RECON_RESULTS!$A$2:$A$1001)-1),2))) | E4: =IF(B4="","",INDEX(RECON_RESULTS!$G$2:$G$1001,SMALL(IF(RECON_RESULTS!$A$2:$A$1001="Unmatched Bank",ROW(RECON_RESULTS!$A$2:$A$1001)-1),2))) | F4: =IF(B4="","",INDEX(RECON_RESULTS!$H$2:$H$1001,SMALL(IF(RECON_RESULTS!$A$2:$A$1001="Unmatched Bank",ROW(RECON_RESULTS!$A$2:$A$1001)-1),2)))
B5: =IFERROR(INDEX(RECON_RESULTS!$A$2:$A$1001,SMALL(IF(RECON_RESULTS!$A$2:$A$1001="Unmatched Bank",ROW(RECON_RESULTS!$A$2:$A$1001)-1),3)),"") | C5: =IF(B5="","",INDEX(RECON_RESULTS!$F$2:$F$1001,SMALL(IF(RECON_RESULTS!$A$2:$A$1001="Unmatched Bank",ROW(RECON_RESULTS!$A$2:$A$1001)-1),3))) | D5: =IF(B5="","",INDEX(RECON_RESULTS!$O$2:$O$1001,SMALL(IF(RECON_RESULTS!$A$2:$A$1001="Unmatched Bank",ROW(RECON_RESULTS!$A$2:$A$1001)-1),3))) | E5: =IF(B5="","",INDEX(RECON_RESULTS!$G$2:$G$1001,SMALL(IF(RECON_RESULTS!$A$2:$A$1001="Unmatched Bank",ROW(RECON_RESULTS!$A$2:$A$1001)-1),3))) | F5: =IF(B5="","",INDEX(RECON_RESULTS!$H$2:$H$1001,SMALL(IF(RECON_RESULTS!$A$2:$A$1001="Unmatched Bank",ROW(RECON_RESULTS!$A$2:$A$1001)-1),3)))
B6: =IFERROR(INDEX(RECON_RESULTS!$A$2:$A$1001,SMALL(IF(RECON_RESULTS!$A$2:$A$1001="Unmatched Bank",ROW(RECON_RESULTS!$A$2:$A$1001)-1),4)),"") | C6: =IF(B6="","",INDEX(RECON_RESULTS!$F$2:$F$1001,SMALL(IF(RECON_RESULTS!$A$2:$A$1001="Unmatched Bank",ROW(RECON_RESULTS!$A$2:$A$1001)-1),4))) | D6: =IF(B6="","",INDEX(RECON_RESULTS!$O$2:$O$1001,SMALL(IF(RECON_RESULTS!$A$2:$A$1001="Unmatched Bank",ROW(RECON_RESULTS!$A$2:$A$1001)-1),4))) | E6: =IF(B6="","",INDEX(RECON_RESULTS!$G$2:$G$1001,SMALL(IF(RECON_RESULTS!$A$2:$A$1001="Unmatched Bank",ROW(RECON_RESULTS!$A$2:$A$1001)-1),4))) | F6: =IF(B6="","",INDEX(RECON_RESULTS!$H$2:$H$1001,SMALL(IF(RECON_RESULTS!$A$2:$A$1001="Unmatched Bank",ROW(RECON_RESULTS!$A$2:$A$1001)-1),4)))
B7: =IFERROR(INDEX(RECON_RESULTS!$A$2:$A$1001,SMALL(IF(RECON_RESULTS!$A$2:$A$1001="Unmatched Bank",ROW(RECON_RESULTS!$A$2:$A$1001)-1),5)),"") | C7: =IF(B7="","",INDEX(RECON_RESULTS!$F$2:$F$1001,SMALL(IF(RECON_RESULTS!$A$2:$A$1001="Unmatched Bank",ROW(RECON_RESULTS!$A$2:$A$1001)-1),5))) | D7: =IF(B7="","",INDEX(RECON_RESULTS!$O$2:$O$1001,SMALL(IF(RECON_RESULTS!$A$2:$A$1001="Unmatched Bank",ROW(RECON_RESULTS!$A$2:$A$1001)-1),5))) | E7: =IF(B7="","",INDEX(RECON_RESULTS!$G$2:$G$1001,SMALL(IF(RECON_RESULTS!$A$2:$A$1001="Unmatched Bank",ROW(RECON_RESULTS!$A$2:$A$1001)-1),5))) | F7: =IF(B7="","",INDEX(RECON_RESULTS!$H$2:$H$1001,SMALL(IF(RECON_RESULTS!$A$2:$A$1001="Unmatched Bank",ROW(RECON_RESULTS!$A$2:$A$1001)-1),5)))
B8: =IFERROR(INDEX(RECON_RESULTS!$A$2:$A$1001,SMALL(IF(RECON_RESULTS!$A$2:$A$1001="Unmatched Bank",ROW(RECON_RESULTS!$A$2:$A$1001)-1),6)),"") | C8: =IF(B8="","",INDEX(RECON_RESULTS!$F$2:$F$1001,SMALL(IF(RECON_RESULTS!$A$2:$A$1001="Unmatched Bank",ROW(RECON_RESULTS!$A$2:$A$1001)-1),6))) | D8: =IF(B8="","",INDEX(RECON_RESULTS!$O$2:$O$1001,SMALL(IF(RECON_RESULTS!$A$2:$A$1001="Unmatched Bank",ROW(RECON_RESULTS!$A$2:$A$1001)-1),6))) | E8: =IF(B8="","",INDEX(RECON_RESULTS!$G$2:$G$1001,SMALL(IF(RECON_RESULTS!$A$2:$A$1001="Unmatched Bank",ROW(RECON_RESULTS!$A$2:$A$1001)-1),6))) | F8: =IF(B8="","",INDEX(RECON_RESULTS!$H$2:$H$1001,SMALL(IF(RECON_RESULTS!$A$2:$A$1001="Unmatched Bank",ROW(RECON_RESULTS!$A$2:$A$1001)-1),6)))
B9: =IFERROR(INDEX(RECON_RESULTS!$A$2:$A$1001,SMALL(IF(RECON_RESULTS!$A$2:$A$1001="Unmatched Bank",ROW(RECON_RESULTS!$A$2:$A$1001)-1),7)),"") | C9: =IF(B9="","",INDEX(RECON_RESULTS!$F$2:$F$1001,SMALL(IF(RECON_RESULTS!$A$2:$A$1001="Unmatched Bank",ROW(RECON_RESULTS!$A$2:$A$1001)-1),7))) | D9: =IF(B9="","",INDEX(RECON_RESULTS!$O$2:$O$1001,SMALL(IF(RECON_RESULTS!$A$2:$A$1001="Unmatched Bank",ROW(RECON_RESULTS!$A$2:$A$1001)-1),7))) | E9: =IF(B9="","",INDEX(RECON_RESULTS!$G$2:$G$1001,SMALL(IF(RECON_RESULTS!$A$2:$A$1001="Unmatched Bank",ROW(RECON_RESULTS!$A$2:$A$1001)-1),7))) | F9: =IF(B9="","",INDEX(RECON_RESULTS!$H$2:$H$1001,SMALL(IF(RECON_RESULTS!$A$2:$A$1001="Unmatched Bank",ROW(RECON_RESULTS!$A$2:$A$1001)-1),7)))
B10: =IFERROR(INDEX(RECON_RESULTS!$A$2:$A$1001,SMALL(IF(RECON_RESULTS!$A$2:$A$1001="Unmatched Bank",ROW(RECON_RESULTS!$A$2:$A$1001)-1),8)),"") | C10: =IF(B10="","",INDEX(RECON_RESULTS!$F$2:$F$1001,SMALL(IF(RECON_RESULTS!$A$2:$A$1001="Unmatched Bank",ROW(RECON_RESULTS!$A$2:$A$1001)-1),8))) | D10: =IF(B10="","",INDEX(RECON_RESULTS!$O$2:$O$1001,SMALL(IF(RECON_RESULTS!$A$2:$A$1001="Unmatched Bank",ROW(RECON_RESULTS!$A$2:$A$1001)-1),8))) | E10: =IF(B10="","",INDEX(RECON_RESULTS!$G$2:$G$1001,SMALL(IF(RECON_RESULTS!$A$2:$A$1001="Unmatched Bank",ROW(RECON_RESULTS!$A$2:$A$1001)-1),8))) | F10: =IF(B10="","",INDEX(RECON_RESULTS!$H$2:$H$1001,SMALL(IF(RECON_RESULTS!$A$2:$A$1001="Unmatched Bank",ROW(RECON_RESULTS!$A$2:$A$1001)-1),8)))
B11: =IFERROR(INDEX(RECON_RESULTS!$A$2:$A$1001,SMALL(IF(RECON_RESULTS!$A$2:$A$1001="Unmatched Bank",ROW(RECON_RESULTS!$A$2:$A$1001)-1),9)),"") | C11: =IF(B11="","",INDEX(RECON_RESULTS!$F$2:$F$1001,SMALL(IF(RECON_RESULTS!$A$2:$A$1001="Unmatched Bank",ROW(RECON_RESULTS!$A$2:$A$1001)-1),9))) | D11: =IF(B11="","",INDEX(RECON_RESULTS!$O$2:$O$1001,SMALL(IF(RECON_RESULTS!$A$2:$A$1001="Unmatched Bank",ROW(RECON_RESULTS!$A$2:$A$1001)-1),9))) | E11: =IF(B11="","",INDEX(RECON_RESULTS!$G$2:$G$1001,SMALL(IF(RECON_RESULTS!$A$2:$A$1001="Unmatched Bank",ROW(RECON_RESULTS!$A$2:$A$1001)-1),9))) | F11: =IF(B11="","",INDEX(RECON_RESULTS!$H$2:$H$1001,SMALL(IF(RECON_RESULTS!$A$2:$A$1001="Unmatched Bank",ROW(RECON_RESULTS!$A$2:$A$1001)-1),9)))
B12: =IFERROR(INDEX(RECON_RESULTS!$A$2:$A$1001,SMALL(IF(RECON_RESULTS!$A$2:$A$1001="Unmatched Bank",ROW(RECON_RESULTS!$A$2:$A$1001)-1),10)),"") | C12: =IF(B12="","",INDEX(RECON_RESULTS!$F$2:$F$1001,SMALL(IF(RECON_RESULTS!$A$2:$A$1001="Unmatched Bank",ROW(RECON_RESULTS!$A$2:$A$1001)-1),10))) | D12: =IF(B12="","",INDEX(RECON_RESULTS!$O$2:$O$1001,SMALL(IF(RECON_RESULTS!$A$2:$A$1001="Unmatched Bank",ROW(RECON_RESULTS!$A$2:$A$1001)-1),10))) | E12: =IF(B12="","",INDEX(RECON_RESULTS!$G$2:$G$1001,SMALL(IF(RECON_RESULTS!$A$2:$A$1001="Unmatched Bank",ROW(RECON_RESULTS!$A$2:$A$1001)-1),10))) | F12: =IF(B12="","",INDEX(RECON_RESULTS!$H$2:$H$1001,SMALL(IF(RECON_RESULTS!$A$2:$A$1001="Unmatched Bank",ROW(RECON_RESULTS!$A$2:$A$1001)-1),10)))
B13: =IFERROR(INDEX(RECON_RESULTS!$A$2:$A$1001,SMALL(IF(RECON_RESULTS!$A$2:$A$1001="Unmatched Bank",ROW(RECON_RESULTS!$A$2:$A$1001)-1),11)),"") | C13: =IF(B13="","",INDEX(RECON_RESULTS!$F$2:$F$1001,SMALL(IF(RECON_RESULTS!$A$2:$A$1001="Unmatched Bank",ROW(RECON_RESULTS!$A$2:$A$1001)-1),11))) | D13: =IF(B13="","",INDEX(RECON_RESULTS!$O$2:$O$1001,SMALL(IF(RECON_RESULTS!$A$2:$A$1001="Unmatched Bank",ROW(RECON_RESULTS!$A$2:$A$1001)-1),11))) | E13: =IF(B13="","",INDEX(RECON_RESULTS!$G$2:$G$1001,SMALL(IF(RECON_RESULTS!$A$2:$A$1001="Unmatched Bank",ROW(RECON_RESULTS!$A$2:$A$1001)-1),11))) | F13: =IF(B13="","",INDEX(RECON_RESULTS!$H$2:$H$1001,SMALL(IF(RECON_RESULTS!$A$2:$A$1001="Unmatched Bank",ROW(RECON_RESULTS!$A$2:$A$1001)-1),11)))
B14: =IFERROR(INDEX(RECON_RESULTS!$A$2:$A$1001,SMALL(IF(RECON_RESULTS!$A$2:$A$1001="Unmatched Bank",ROW(RECON_RESULTS!$A$2:$A$1001)-1),12)),"") | C14: =IF(B14="","",INDEX(RECON_RESULTS!$F$2:$F$1001,SMALL(IF(RECON_RESULTS!$A$2:$A$1001="Unmatched Bank",ROW(RECON_RESULTS!$A$2:$A$1001)-1),12))) | D14: =IF(B14="","",INDEX(RECON_RESULTS!$O$2:$O$1001,SMALL(IF(RECON_RESULTS!$A$2:$A$1001="Unmatched Bank",ROW(RECON_RESULTS!$A$2:$A$1001)-1),12))) | E14: =IF(B14="","",INDEX(RECON_RESULTS!$G$2:$G$1001,SMALL(IF(RECON_RESULTS!$A$2:$A$1001="Unmatched Bank",ROW(RECON_RESULTS!$A$2:$A$1001)-1),12))) | F14: =IF(B14="","",INDEX(RECON_RESULTS!$H$2:$H$1001,SMALL(IF(RECON_RESULTS!$A$2:$A$1001="Unmatched Bank",ROW(RECON_RESULTS!$A$2:$A$1001)-1),12)))
B15: =IFERROR(INDEX(RECON_RESULTS!$A$2:$A$1001,SMALL(IF(RECON_RESULTS!$A$2:$A$1001="Unmatched Bank",ROW(RECON_RESULTS!$A$2:$A$1001)-1),13)),"") | C15: =IF(B15="","",INDEX(RECON_RESULTS!$F$2:$F$1001,SMALL(IF(RECON_RESULTS!$A$2:$A$1001="Unmatched Bank",ROW(RECON_RESULTS!$A$2:$A$1001)-1),13))) | D15: =IF(B15="","",INDEX(RECON_RESULTS!$O$2:$O$1001,SMALL(IF(RECON_RESULTS!$A$2:$A$1001="Unmatched Bank",ROW(RECON_RESULTS!$A$2:$A$1001)-1),13))) | E15: =IF(B15="","",INDEX(RECON_RESULTS!$G$2:$G$1001,SMALL(IF(RECON_RESULTS!$A$2:$A$1001="Unmatched Bank",ROW(RECON_RESULTS!$A$2:$A$1001)-1),13))) | F15: =IF(B15="","",INDEX(RECON_RESULTS!$H$2:$H$1001,SMALL(IF(RECON_RESULTS!$A$2:$A$1001="Unmatched Bank",ROW(RECON_RESULTS!$A$2:$A$1001)-1),13)))
B16: =IFERROR(INDEX(RECON_RESULTS!$A$2:$A$1001,SMALL(IF(RECON_RESULTS!$A$2:$A$1001="Unmatched Bank",ROW(RECON_RESULTS!$A$2:$A$1001)-1),14)),"") | C16: =IF(B16="","",INDEX(RECON_RESULTS!$F$2:$F$1001,SMALL(IF(RECON_RESULTS!$A$2:$A$1001="Unmatched Bank",ROW(RECON_RESULTS!$A$2:$A$1001)-1),14))) | D16: =IF(B16="","",INDEX(RECON_RESULTS!$O$2:$O$1001,SMALL(IF(RECON_RESULTS!$A$2:$A$1001="Unmatched Bank",ROW(RECON_RESULTS!$A$2:$A$1001)-1),14))) | E16: =IF(B16="","",INDEX(RECON_RESULTS!$G$2:$G$1001,SMALL(IF(RECON_RESULTS!$A$2:$A$1001="Unmatched Bank",ROW(RECON_RESULTS!$A$2:$A$1001)-1),14))) | F16: =IF(B16="","",INDEX(RECON_RESULTS!$H$2:$H$1001,SMALL(IF(RECON_RESULTS!$A$2:$A$1001="Unmatched Bank",ROW(RECON_RESULTS!$A$2:$A$1001)-1),14)))
B17: =IFERROR(INDEX(RECON_RESULTS!$A$2:$A$1001,SMALL(IF(RECON_RESULTS!$A$2:$A$1001="Unmatched Bank",ROW(RECON_RESULTS!$A$2:$A$1001)-1),15)),"") | C17: =IF(B17="","",INDEX(RECON_RESULTS!$F$2:$F$1001,SMALL(IF(RECON_RESULTS!$A$2:$A$1001="Unmatched Bank",ROW(RECON_RESULTS!$A$2:$A$1001)-1),15))) | D17: =IF(B17="","",INDEX(RECON_RESULTS!$O$2:$O$1001,SMALL(IF(RECON_RESULTS!$A$2:$A$1001="Unmatched Bank",ROW(RECON_RESULTS!$A$2:$A$1001)-1),15))) | E17: =IF(B17="","",INDEX(RECON_RESULTS!$G$2:$G$1001,SMALL(IF(RECON_RESULTS!$A$2:$A$1001="Unmatched Bank",ROW(RECON_RESULTS!$A$2:$A$1001)-1),15))) | F17: =IF(B17="","",INDEX(RECON_RESULTS!$H$2:$H$1001,SMALL(IF(RECON_RESULTS!$A$2:$A$1001="Unmatched Bank",ROW(RECON_RESULTS!$A$2:$A$1001)-1),15)))
B18: =IFERROR(INDEX(RECON_RESULTS!$A$2:$A$1001,SMALL(IF(RECON_RESULTS!$A$2:$A$1001="Unmatched Bank",ROW(RECON_RESULTS!$A$2:$A$1001)-1),16)),"") | C18: =IF(B18="","",INDEX(RECON_RESULTS!$F$2:$F$1001,SMALL(IF(RECON_RESULTS!$A$2:$A$1001="Unmatched Bank",ROW(RECON_RESULTS!$A$2:$A$1001)-1),16))) | D18: =IF(B18="","",INDEX(RECON_RESULTS!$O$2:$O$1001,SMALL(IF(RECON_RESULTS!$A$2:$A$1001="Unmatched Bank",ROW(RECON_RESULTS!$A$2:$A$1001)-1),16))) | E18: =IF(B18="","",INDEX(RECON_RESULTS!$G$2:$G$1001,SMALL(IF(RECON_RESULTS!$A$2:$A$1001="Unmatched Bank",ROW(RECON_RESULTS!$A$2:$A$1001)-1),16))) | F18: =IF(B18="","",INDEX(RECON_RESULTS!$H$2:$H$1001,SMALL(IF(RECON_RESULTS!$A$2:$A$1001="Unmatched Bank",ROW(RECON_RESULTS!$A$2:$A$1001)-1),16)))
B19: =IFERROR(INDEX(RECON_RESULTS!$A$2:$A$1001,SMALL(IF(RECON_RESULTS!$A$2:$A$1001="Unmatched Bank",ROW(RECON_RESULTS!$A$2:$A$1001)-1),17)),"") | C19: =IF(B19="","",INDEX(RECON_RESULTS!$F$2:$F$1001,SMALL(IF(RECON_RESULTS!$A$2:$A$1001="Unmatched Bank",ROW(RECON_RESULTS!$A$2:$A$1001)-1),17))) | D19: =IF(B19="","",INDEX(RECON_RESULTS!$O$2:$O$1001,SMALL(IF(RECON_RESULTS!$A$2:$A$1001="Unmatched Bank",ROW(RECON_RESULTS!$A$2:$A$1001)-1),17))) | E19: =IF(B19="","",INDEX(RECON_RESULTS!$G$2:$G$1001,SMALL(IF(RECON_RESULTS!$A$2:$A$1001="Unmatched Bank",ROW(RECON_RESULTS!$A$2:$A$1001)-1),17))) | F19: =IF(B19="","",INDEX(RECON_RESULTS!$H$2:$H$1001,SMALL(IF(RECON_RESULTS!$A$2:$A$1001="Unmatched Bank",ROW(RECON_RESULTS!$A$2:$A$1001)-1),17)))
B20: =IFERROR(INDEX(RECON_RESULTS!$A$2:$A$1001,SMALL(IF(RECON_RESULTS!$A$2:$A$1001="Unmatched Bank",ROW(RECON_RESULTS!$A$2:$A$1001)-1),18)),"") | C20: =IF(B20="","",INDEX(RECON_RESULTS!$F$2:$F$1001,SMALL(IF(RECON_RESULTS!$A$2:$A$1001="Unmatched Bank",ROW(RECON_RESULTS!$A$2:$A$1001)-1),18))) | D20: =IF(B20="","",INDEX(RECON_RESULTS!$O$2:$O$1001,SMALL(IF(RECON_RESULTS!$A$2:$A$1001="Unmatched Bank",ROW(RECON_RESULTS!$A$2:$A$1001)-1),18))) | E20: =IF(B20="","",INDEX(RECON_RESULTS!$G$2:$G$1001,SMALL(IF(RECON_RESULTS!$A$2:$A$1001="Unmatched Bank",ROW(RECON_RESULTS!$A$2:$A$1001)-1),18))) | F20: =IF(B20="","",INDEX(RECON_RESULTS!$H$2:$H$1001,SMALL(IF(RECON_RESULTS!$A$2:$A$1001="Unmatched Bank",ROW(RECON_RESULTS!$A$2:$A$1001)-1),18)))
B21: =IFERROR(INDEX(RECON_RESULTS!$A$2:$A$1001,SMALL(IF(RECON_RESULTS!$A$2:$A$1001="Unmatched Bank",ROW(RECON_RESULTS!$A$2:$A$1001)-1),19)),"") | C21: =IF(B21="","",INDEX(RECON_RESULTS!$F$2:$F$1001,SMALL(IF(RECON_RESULTS!$A$2:$A$1001="Unmatched Bank",ROW(RECON_RESULTS!$A$2:$A$1001)-1),19))) | D21: =IF(B21="","",INDEX(RECON_RESULTS!$O$2:$O$1001,SMALL(IF(RECON_RESULTS!$A$2:$A$1001="Unmatched Bank",ROW(RECON_RESULTS!$A$2:$A$1001)-1),19))) | E21: =IF(B21="","",INDEX(RECON_RESULTS!$G$2:$G$1001,SMALL(IF(RECON_RESULTS!$A$2:$A$1001="Unmatched Bank",ROW(RECON_RESULTS!$A$2:$A$1001)-1),19))) | F21: =IF(B21="","",INDEX(RECON_RESULTS!$H$2:$H$1001,SMALL(IF(RECON_RESULTS!$A$2:$A$1001="Unmatched Bank",ROW(RECON_RESULTS!$A$2:$A$1001)-1),19)))
B22: =IFERROR(INDEX(RECON_RESULTS!$A$2:$A$1001,SMALL(IF(RECON_RESULTS!$A$2:$A$1001="Unmatched Bank",ROW(RECON_RESULTS!$A$2:$A$1001)-1),20)),"") | C22: =IF(B22="","",INDEX(RECON_RESULTS!$F$2:$F$1001,SMALL(IF(RECON_RESULTS!$A$2:$A$1001="Unmatched Bank",ROW(RECON_RESULTS!$A$2:$A$1001)-1),20))) | D22: =IF(B22="","",INDEX(RECON_RESULTS!$O$2:$O$1001,SMALL(IF(RECON_RESULTS!$A$2:$A$1001="Unmatched Bank",ROW(RECON_RESULTS!$A$2:$A$1001)-1),20))) | E22: =IF(B22="","",INDEX(RECON_RESULTS!$G$2:$G$1001,SMALL(IF(RECON_RESULTS!$A$2:$A$1001="Unmatched Bank",ROW(RECON_RESULTS!$A$2:$A$1001)-1),20))) | F22: =IF(B22="","",INDEX(RECON_RESULTS!$H$2:$H$1001,SMALL(IF(RECON_RESULTS!$A$2:$A$1001="Unmatched Bank",ROW(RECON_RESULTS!$A$2:$A$1001)-1),20)))
B23: =IFERROR(INDEX(RECON_RESULTS!$A$2:$A$1001,SMALL(IF(RECON_RESULTS!$A$2:$A$1001="Unmatched Bank",ROW(RECON_RESULTS!$A$2:$A$1001)-1),21)),"") | C23: =IF(B23="","",INDEX(RECON_RESULTS!$F$2:$F$1001,SMALL(IF(RECON_RESULTS!$A$2:$A$1001="Unmatched Bank",ROW(RECON_RESULTS!$A$2:$A$1001)-1),21))) | D23: =IF(B23="","",INDEX(RECON_RESULTS!$O$2:$O$1001,SMALL(IF(RECON_RESULTS!$A$2:$A$1001="Unmatched Bank",ROW(RECON_RESULTS!$A$2:$A$1001)-1),21))) | E23: =IF(B23="","",INDEX(RECON_RESULTS!$G$2:$G$1001,SMALL(IF(RECON_RESULTS!$A$2:$A$1001="Unmatched Bank",ROW(RECON_RESULTS!$A$2:$A$1001)-1),21))) | F23: =IF(B23="","",INDEX(RECON_RESULTS!$H$2:$H$1001,SMALL(IF(RECON_RESULTS!$A$2:$A$1001="Unmatched Bank",ROW(RECON_RESULTS!$A$2:$A$1001)-1),21)))
